Workbook

Sheet Input_Complete
A1: Год | B1: Компания | C1: Период анализа | D1: Валюта | E1: Масштаб | F1: Тип данных | G1: Основной источник | H1: Источник notes / MD&A | I1: Ограничение / комментарий | J1: Выручка всего | K1: Себестоимость / прямые операционные расходы | L1: Валовая прибыль расчетная | M1: Операционные расходы всего | N1: Операционная прибыль | O1: Финансовые доходы | P1: Финансовые расходы | Q1: Курсовая разница, нетто | R1: Налог на прибыль | S1: Чистая прибыль | T1: Активы всего | U1: Денежные средства | V1: Дебиторская задолженность | W1: Запасы | X1: Основные средства | Y1: Нематериальные активы | Z1: Обязательства всего | AA1: Займы долгосрочные | AB1: Займы краткосрочные | AC1: Займы всего | AD1: Обязательства по аренде долгосрочные | AE1: Обязательства по аренде краткосрочные | AF1: Обязательства по аренде всего | AG1: Итого долг | AH1: Чистый долг | AI1: Капитал | AJ1: CFO | AK1: CFI | AL1: CFF | AM1: Capex | AN1: Дивиденды выплаченные | AO1: Амортизация | AP1: FCF | AQ1: CFO / чистая прибыль | AR1: Операционная маржа | AS1: Расчетная валовая маржа | AT1: Чистая маржа | AU1: ROA | AV1: ROE | AW1: Debt / Assets | AX1: Debt / Equity | AY1: Current ratio | AZ1: Quick ratio | BA1: Cash ratio | BB1: Interest coverage | BC1: Asset turnover | BD1: Receivables turnover | BE1: Inventory turnover | BF1: DSO, дней | BG1: DIO, дней | BH1: CFO / Capex | BI1: Fuel costs / revenue | BJ1: Lease liabilities / assets | BK1: Operating expenses / revenue | BL1: Пассажирская выручка / общая выручка | BM1: Capex / revenue
A2: 2021 | B2: Air Astana | C2: 2021-2025 | D2: KZT | E2: тыс. тенге | F2: Фактические исторические данные | G2: Годовая финансовая отчетность Air Astana 2021; Баланс, ОПиУ, ОДДС | H2: Notes/MD&A из годового отчета соответствующего года; см. лист Источники | I2: Air Astana не раскрывает классическую себестоимость отдельной строкой; для Input использована расчетная себестоимость как сумма основных прямых операционных расходов: топливо, персонал/экипаж, техническое обслуживание, аэропортовое обслуживание и обслуживание пассажиров. | J2: 324906724 | K2: -204035110 | L2: 120871614 | M2: -281291651 | N2: 43615073 | O2: 1026620 | P2: -20040053 | Q2: -5330611 | R2: -3785461 | S2: 15485568 | T2: 475926936 | U2: 97740953 | V2: 6103061 | W2: 22261449 | X2: 311845960 | Y2: 659790 | Z2: 448302964 | AA2: 2054936 | AB2: 24840159 | AC2: 26895095 | AD2: 250676740 | AE2: 63195657 | AF2: 313872397 | AG2: 340767492 | AH2: 243026539 | AI2: 27623972 | AJ2: 118067404 | AK2: -5562362 | AL2: -101243828 | AM2: 13497482 | AN2: 0 | AO2: 51484170 | AP2: 104569922 | AQ2: 7.6243509 | AR2: 0.13423875 | AS2: 0.37201943 | AT2: 0.047661581 | AU2: 0.0325377 | AV2: 0.56058441 | AW2: 0.716008 | AX2: 12.335934 | AY2: 0.92607718 | AZ2: 0.68370244 | BA2: 0.6406644 | BB2: 2.1763951 | BC2: 0.68268194 | BD2: 53.236683 | BE2: 14.595039 | BF2: 6.8561747 | BG2: 39.82368 | BH2: 8.7473652 | BI2: 0.17937182 | BJ2: 0.65949702 | BK2: 0.86576125 | BL2: 0.93950853 | BM2: 0.041542637
A3: 2022 | B3: Air Astana | C3: 2021-2025 | D3: KZT | E3: тыс. тенге | F3: Фактические исторические данные | G3: Годовая финансовая отчетность Air Astana 2022; Баланс, ОПиУ, ОДДС | H3: Notes/MD&A из годового отчета соответствующего года; см. лист Источники | I3: Air Astana не раскрывает классическую себестоимость отдельной строкой; для Input использована расчетная себестоимость как сумма основных прямых операционных расходов: топливо, персонал/экипаж, техническое обслуживание, аэропортовое обслуживание и обслуживание пассажиров. | J3: 477981818 | K3: -310335336 | L3: 167646482 | M3: -407871344 | N3: 70110474 | O3: 3261294 | P3: -18073217 | Q3: -6923638 | R3: -10792015 | S3: 37582898 | T3: 578717319 | U3: 116998633 | V3: 9857684 | W3: 22750814 | X3: 378255700 | Y3: 718495 | Z3: 508270527 | AA3: 1925549 | AB3: 3670665 | AC3: 5596214 | AD3: 265658719 | AE3: 73373051 | AF3: 339031770 | AG3: 344627984 | AH3: 227629351 | AI3: 70446792 | AJ3: 163230844 | AK3: -27796835 | AL3: -119154847 | AM3: 22227370 | AN3: 0 | AO3: 62243853 | AP3: 141003474 | AQ3: 4.3432213 | AR3: 0.14668021 | AS3: 0.3507382 | AT3: 0.0786283 | AU3: 0.06494172 | AV3: 0.53349339 | AW3: 0.59550315 | AX3: 4.8920323 | AY3: 0.91726416 | AZ3: 0.69841354 | BA3: 0.63635728 | BB3: 3.8792471 | BC3: 0.82593315 | BD3: 48.488247 | BE3: 21.009438 | BF3: 7.5275973 | BG3: 26.758304 | BH3: 7.3436868 | BI3: 0.22373354 | BJ3: 0.58583312 | BK3: 0.85331979 | BL3: 0.96692364 | BM3: 0.046502543
A4: 2023 | B4: Air Astana | C4: 2021-2025 | D4: KZT | E4: тыс. тенге | F4: Фактические исторические данные | G4: Финансовая отчетность Air Astana 2023; Баланс, ОПиУ, ОДДС | H4: Notes/MD&A из годового отчета соответствующего года; см. лист Источники | I4: Air Astana не раскрывает классическую себестоимость отдельной строкой; для Input использована расчетная себестоимость как сумма основных прямых операционных расходов: топливо, персонал/экипаж, техническое обслуживание, аэропортовое обслуживание и обслуживание пассажиров. | J4: 535169502 | K4: -359214052 | L4: 175955450 | M4: -473883363 | N4: 61286139 | O4: 6757281 | P4: -22765053 | Q4: -6280403 | R4: -8258890 | S4: 30739074 | T4: 619312543 | U4: 124552167 | V4: 10693524 | W4: 30704619 | X4: 387885139 | Y4: 1289132 | Z4: 522328078 | AA4: 0 | AB4: 187279 | AC4: 187279 | AD4: 247233366 | AE4: 79546636 | AF4: 326780002 | AG4: 326967281 | AH4: 202415114 | AI4: 96984465 | AJ4: 142827723 | AK4: -20967276 | AL4: -111377266 | AM4: 19035768 | AN4: 7644016 | AO4: 73820615 | AP4: 123791955 | AQ4: 4.646455 | AR4: 0.11451725 | AS4: 0.32878452 | AT4: 0.057438015 | AU4: 0.049634186 | AV4: 0.31694843 | AW4: 0.52795198 | AX4: 3.3713366 | AY4: 0.91271811 | AZ4: 0.65856852 | BA4: 0.60263231 | BB4: 2.6921149 | BC4: 0.86413477 | BD4: 50.046131 | BE4: 17.429609 | BF4: 7.2932711 | BG4: 31.199186 | BH4: 7.5031238 | BI4: 0.23797651 | BJ4: 0.52764958 | BK4: 0.88548275 | BL4: 0.97366299 | BM4: 0.035569605
A5: 2024 | B5: Air Astana | C5: 2021-2025 | D5: KZT | E5: тыс. тенге | F5: Фактические исторические данные | G5: Финансовая отчетность Air Astana 2024; Баланс, ОПиУ, ОДДС | H5: Notes/MD&A из годового отчета соответствующего года; см. лист Источники | I5: Air Astana не раскрывает классическую себестоимость отдельной строкой; для Input использована расчетная себестоимость как сумма основных прямых операционных расходов: топливо, персонал/экипаж, техническое обслуживание, аэропортовое обслуживание и обслуживание пассажиров. | J5: 616152033 | K5: -418011730 | L5: 198140303 | M5: -553829486 | N5: 62322547 | O5: 10376957 | P5: -30618503 | Q5: -9939963 | R5: -6618444 | S5: 25522594 | T5: 952063811 | U5: 256622307 | V5: 10922813 | W5: 34724999 | X5: 558341061 | Y5: 3160112 | Z5: 744892164 | AA5: 273582 | AB5: 29406 | AC5: 302988 | AD5: 376385720 | AE5: 90259057 | AF5: 466644777 | AG5: 466947765 | AH5: 210325458 | AI5: 207171647 | AJ5: 173127148 | AK5: -8509373 | AL5: -62191375 | AM5: 46099340 | AN5: 0 | AO5: 89033552 | AP5: 127027808 | AQ5: 6.7832897 | AR5: 0.101148 | AS5: 0.32157697 | AT5: 0.041422559 | AU5: 0.026807651 | AV5: 0.1231954 | AW5: 0.49045848 | AX5: 2.2539173 | AY5: 1.5497035 | AZ5: 1.2496048 | BA5: 1.1910514 | BB5: 2.0354538 | BC5: 0.64717514 | BD5: 56.409648 | BE5: 17.74376 | BF5: 6.4705244 | BG5: 30.321218 | BH5: 3.7555234 | BI5: 0.23269114 | BJ5: 0.49014023 | BK5: 0.898852 | BL5: 0.95075567 | BM5: 0.074818125
A6: 2025 | B6: Air Astana | C6: 2021-2025 | D6: KZT | E6: тыс. тенге | F6: Фактические исторические данные | G6: Финансовая отчетность Air Astana 2025; Баланс, ОПиУ, ОДДС | H6: Notes/MD&A из годового отчета соответствующего года; см. лист Источники | I6: Air Astana не раскрывает классическую себестоимость отдельной строкой; для Input использована расчетная себестоимость как сумма основных прямых операционных расходов: топливо, персонал/экипаж, техническое обслуживание, аэропортовое обслуживание и обслуживание пассажиров. | J6: 758966733 | K6: -532414996 | L6: 226551737 | M6: -713117652 | N6: 45849081 | O6: 11633517 | P6: -42893475 | Q6: -4142993 | R6: -3423268 | S6: 7022862 | T6: 1039663393 | U6: 239053004 | V6: 13142263 | W6: 43686386 | X6: 604500136 | Y6: 3286956 | Z6: 852964087 | AA6: 2509956 | AB6: 316967 | AC6: 2826923 | AD6: 427807796 | AE6: 100151054 | AF6: 527958850 | AG6: 530785773 | AH6: 291732769 | AI6: 186699306 | AJ6: 127590876 | AK6: 17598903 | AL6: -152510081 | AM6: 28152607 | AN6: 19393090 | AO6: 119929168 | AP6: 99438269 | AQ6: 18.167932 | AR6: 0.060409869 | AS6: 0.29850022 | AT6: 0.0092531882 | AU6: 0.0067549382 | AV6: 0.037615898 | AW6: 0.51053618 | AX6: 2.8429981 | AY6: 1.2382705 | AZ6: 0.96336416 | BA6: 0.8292957 | BB6: 1.0689057 | BC6: 0.73001198 | BD6: 57.750079 | BE6: 17.373072 | BF6: 6.3203376 | BG6: 29.94944 | BH6: 4.5321158 | BI6: 0.22812303 | BJ6: 0.5078171 | BK6: 0.93959013 | BL6: 0.95003703 | BM6: 0.037093335

Sheet Checks_Complete
A1: Проверка | B1: 2021 | C1: 2022 | D1: 2023 | E1: 2024 | F1: 2025 | G1: Ожидаемый результат | H1: Комментарий
A2: Баланс: активы - обязательства - капитал | B2: 0 | C2: 0 | D2: 0 | E2: 0 | F2: 0 | G2: 0 | H2: Базовая арифметика баланса должна сходиться
A3: Валюта | B3: KZT | C3: KZT | D3: KZT | E3: KZT | F3: KZT | G3: KZT | H3: Единая валюта для всех лет
A4: Масштаб | B4: тыс. тенге | C4: тыс. тенге | D4: тыс. тенге | E4: тыс. тенге | F4: тыс. тенге | G4: тыс. тенге | H4: Единый масштаб для всех лет
A5: FCF = CFO - Capex | B5: 0 | C5: 0 | D5: 0 | E5: 0 | F5: 0 | G5: 0 | H5: Проверка формулы свободного денежного потока
A6: Долг = займы + аренда | B6: 0 | C6: 0 | D6: 0 | E6: 0 | F6: 0 | G6: 0 | H6: Проверка состава долга
A7: Прямые расходы отрицательные | B7: -204035110 | C7: -310335336 | D7: -359214052 | E7: -418011730 | F7: -532414996 | G7: < 0 | H7: Для расходов в ОПиУ используется знак минус
A8: Дивиденды положительным числом | B8: 0 | C8: 0 | D8: 7644016 | E8: 0 | F8: 19393090 | G8: >= 0 | H8: В input показывается выплаченная сумма как положительное число

Sheet Баланс
A1: тыс. тенге | B1: 2021 | C1: 2022 | D1: 2023 | E1: 2024 | F1: 2025 | G1: Удельный вес 2021,% | H1: Удельный вес 2022,% | I1: Удельный вес 2023,% | J1: Удельный вес 2024,% | K1: Удельный вес 2025,% | L1: Темп прироста 2021-2022,% | M1: Темп прироста 2022-2023,% | N1: Темп прироста 2023-2024,% | O1: Темп прироста 2024-2025,%
A2: Активы
A3: Долгосрочные активы
A4: Основные средства | B4: 311845960 | C4: 378255700 | D4: 387885139 | E4: 558341061 | F4: 604500136 | G4: =B4/$B$19*100 | H4: =C4/$C$19*100 | I4: =D4/$D$19*100 | J4: =E4/$E$19*100 | K4: =F4/$F$19*100 | L4: =(C4-B4)/B4*100 | M4: =(D4-C4)/C4*100 | N4: =(E4-D4)/D4*100 | O4: =(F4-E4)/E4*100
A5: Нематериальные активы | B5: 659790 | C5: 718495 | D5: 1289132 | E5: 3160112 | F5: 3286956 | G5: =B5/$B$19*100 | H5: =C5/$C$19*100 | I5: =D5/$D$19*100 | J5: =E5/$E$19*100 | K5: =F5/$F$19*100 | L5: =(C5-B5)/B5*100 | M5: =(D5-C5)/C5*100 | N5: =(E5-D5)/D5*100 | O5: =(F5-E5)/E5*100
A6: Авансы выданные | B6: 7037908 | C6: 7178940 | D6: 8387087 | E6: 10287430 | F6: 10275403 | G6: =B6/$B$19*100 | H6: =C6/$C$19*100 | I6: =D6/$D$19*100 | J6: =E6/$E$19*100 | K6: =F6/$F$19*100 | L6: =(C6-B6)/B6*100 | M6: =(D6-C6)/C6*100 | N6: =(E6-D6)/D6*100 | O6: =(F6-E6)/E6*100
A7: Гарантийные депозиты | B7: 7761173 | C7: 13657428 | D7: 15137757 | E7: 20319131 | F7: 22723574 | G7: =B7/$B$19*100 | H7: =C7/$C$19*100 | I7: =D7/$D$19*100 | J7: =E7/$E$19*100 | K7: =F7/$F$19*100 | L7: =(C7-B7)/B7*100 | M7: =(D7-C7)/C7*100 | N7: =(E7-D7)/D7*100 | O7: =(F7-E7)/E7*100
A8: Отложенные налоговые активы | B8: 1170610 | C8: 8553011 | D8: 16836902 | E8: 25521921 | F8: 40910015 | G8: =B8/$B$19*100 | H8: =C8/$C$19*100 | I8: =D8/$D$19*100 | J8: =E8/$E$19*100 | K8: =F8/$F$19*100 | L8: =(C8-B8)/B8*100 | M8: =(D8-C8)/C8*100 | N8: =(E8-D8)/D8*100 | O8: =(F8-E8)/E8*100
A9: Торговая и прочая дебиторская задолженность | B9: 1559230 | C9: 601445 | D9: 610474 | E9: 330819 | F9: 839685 | G9: =B9/$B$19*100 | H9: =C9/$C$19*100 | I9: =D9/$D$19*100 | J9: =E9/$E$19*100 | K9: =F9/$F$19*100 | L9: =(C9-B9)/B9*100 | M9: =(D9-C9)/C9*100 | N9: =(E9-D9)/D9*100 | O9: =(F9-E9)/E9*100
A10: Текущие активы
A11: Товарно-материальные запасы | B11: 22261449 | C11: 22750814 | D11: 30704619 | E11: 34724999 | F11: 43686386 | G11: =B11/$B$19*100 | H11: =C11/$C$19*100 | I11: =D11/$D$19*100 | J11: =E11/$E$19*100 | K11: =F11/$F$19*100 | L11: =(C11-B11)/B11*100 | M11: =(D11-C11)/C11*100 | N11: =(E11-D11)/D11*100 | O11: =(F11-E11)/E11*100
A12: Авансы выданные, текущие | B12: 11457381 | C12: 9720739 | D12: 11284452 | E12: 15905582 | F12: 15880719 | G12: =B12/$B$19*100 | H12: =C12/$C$19*100 | I12: =D12/$D$19*100 | J12: =E12/$E$19*100 | K12: =F12/$F$19*100 | L12: =(C12-B12)/B12*100 | M12: =(D12-C12)/C12*100 | N12: =(E12-D12)/D12*100 | O12: =(F12-E12)/E12*100
A13: Предоплата по подоходному налогу | B13: 1135634 | C13: 4153672 | D13: 6027011 | E13: 6825905 | F13: 3591791 | G13: =B13/$B$19*100 | H13: =C13/$C$19*100 | I13: =D13/$D$19*100 | J13: =E13/$E$19*100 | K13: =F13/$F$19*100 | L13: =(C13-B13)/B13*100 | M13: =(D13-C13)/C13*100 | N13: =(E13-D13)/D13*100 | O13: =(F13-E13)/E13*100
A14: Торговая и прочая дебиторская задолженность | B14: 6103061 | C14: 9857684 | D14: 10693524 | E14: 10922813 | F14: 13142263 | G14: =B14/$B$19*100 | H14: =C14/$C$19*100 | I14: =D14/$D$19*100 | J14: =E14/$E$19*100 | K14: =F14/$F$19*100 | L14: =(C14-B14)/B14*100 | M14: =(D14-C14)/C14*100 | N14: =(E14-D14)/D14*100 | O14: =(F14-E14)/E14*100
A15: Предоплата по прочим налогам | B15: 3328746 | C15: 3876082 | D15: 4657876 | E15: 7242317 | F15: 16126407 | G15: =B15/$B$19*100 | H15: =C15/$C$19*100 | I15: =D15/$D$19*100 | J15: =E15/$E$19*100 | K15: =F15/$F$19*100 | L15: =(C15-B15)/B15*100 | M15: =(D15-C15)/C15*100 | N15: =(E15-D15)/D15*100 | O15: =(F15-E15)/E15*100
A16: Гарантийные депозиты, текущие | B16: 677062 | C16: 1626677 | D16: 899574 | E16: 1700831 | F16: 25524210 | G16: =B16/$B$19*100 | H16: =C16/$C$19*100 | I16: =D16/$D$19*100 | J16: =E16/$E$19*100 | K16: =F16/$F$19*100 | L16: =(C16-B16)/B16*100 | M16: =(D16-C16)/C16*100 | N16: =(E16-D16)/D16*100 | O16: =(F16-E16)/E16*100
A17: Денежные средства и их эквиваленты | B17: 97740953 | C17: 116998633 | D17: 124552167 | E17: 256622307 | F17: 239053004 | G17: =B17/$B$19*100 | H17: =C17/$C$19*100 | I17: =D17/$D$19*100 | J17: =E17/$E$19*100 | K17: =F17/$F$19*100 | L17: =(C17-B17)/B17*100 | M17: =(D17-C17)/C17*100 | N17: =(E17-D17)/D17*100 | O17: =(F17-E17)/E17*100
A18: Прочие финансовые активы | B18: 3187979 | C18: 767999 | D18: 346829 | E18: 158583 | F18: 122844 | G18: =B18/$B$19*100 | H18: =C18/$C$19*100 | I18: =D18/$D$19*100 | J18: =E18/$E$19*100 | K18: =F18/$F$19*100 | L18: =(C18-B18)/B18*100 | M18: =(D18-C18)/C18*100 | N18: =(E18-D18)/D18*100 | O18: =(F18-E18)/E18*100
A19: Итого активы | B19: 475926936 | C19: 578717319 | D19: 619312543 | E19: 952063811 | F19: 1039663393 | G19: =B19/$B$19*100 | H19: =C19/$C$19*100 | I19: =D19/$D$19*100 | J19: =E19/$E$19*100 | K19: =F19/$F$19*100 | L19: =(C19-B19)/B19*100 | M19: =(D19-C19)/C19*100 | N19: =(E19-D19)/D19*100 | O19: =(F19-E19)/E19*100
A20: Собственный капитал и обязательства
A21: Собственный капитал
A22: Акционерный капитал | B22: 2501550 | C22: 2501550 | D22: 2501550 | E22: 56758223 | F22: 56758223 | G22: =B22/$B$29*100 | H22: =C22/$C$29*100 | I22: =D22/$D$29*100 | J22: =E22/$E$29*100 | K22: =F22/$F$29*100 | L22: =(C22-B22)/B22*100 | M22: =(D22-C22)/C22*100 | N22: =(E22-D22)/D22*100 | O22: =(F22-E22)/E22*100
A23: Дополнительно оплаченный капитал | B23: 48996 | C23: 48996 | D23: 48996 | E23: 48996 | F23: 48996 | G23: =B23/$B$29*100 | H23: =C23/$C$29*100 | I23: =D23/$D$29*100 | J23: =E23/$E$29*100 | K23: =F23/$F$29*100 | L23: =(C23-B23)/B23*100 | M23: =(D23-C23)/C23*100 | N23: =(E23-D23)/D23*100 | O23: =(F23-E23)/E23*100
A24: Прочие резервы | B24: 0 | C24: 0 | D24: 0 | E24: 1455281 | F24: -691711 | G24: =B24/$B$29*100 | H24: =C24/$C$29*100 | I24: =D24/$D$29*100 | J24: =E24/$E$29*100 | K24: =F24/$F$29*100 | L24: 0 | M24: 0 | N24: 0 | O24: =(F24-E24)/E24*100
A25: Выкупленные акции | B25: 0 | C25: 0 | D25: 0 | E25: -3952306 | F25: -2624585 | G25: =B25/$B$29*100 | H25: =C25/$C$29*100 | I25: =D25/$D$29*100 | J25: =E25/$E$29*100 | K25: =F25/$F$29*100 | L25: 0 | M25: 0 | N25: 0 | O25: =(F25-E25)/E25*100
A26: Резерв по пересчету валюты отчетности | B26: 10002799 | C26: 11930890 | D26: 12323792 | E26: 40842148 | F26: 34332765 | G26: =B26/$B$29*100 | H26: =C26/$C$29*100 | I26: =D26/$D$29*100 | J26: =E26/$E$29*100 | K26: =F26/$F$29*100 | L26: =(C26-B26)/B26*100 | M26: =(D26-C26)/C26*100 | N26: =(E26-D26)/D26*100 | O26: =(F26-E26)/E26*100
A27: Резерв по инструментам хеджирования, за вычетом налога | B27: -11723938 | C27: -8412107 | D27: -5489830 | E27: -1965955 | F27: -60737 | G27: =B27/$B$29*100 | H27: =C27/$C$29*100 | I27: =D27/$D$29*100 | J27: =E27/$E$29*100 | K27: =F27/$F$29*100 | L27: =(C27-B27)/B27*100 | M27: =(D27-C27)/C27*100 | N27: =(E27-D27)/D27*100 | O27: =(F27-E27)/E27*100
A28: Нераспределенная прибыль | B28: 26749565 | C28: 64377463 | D28: 87599957 | E28: 113985260 | F28: 98936355 | G28: =B28/$B$29*100 | H28: =C28/$C$29*100 | I28: =D28/$D$29*100 | J28: =E28/$E$29*100 | K28: =F28/$F$29*100 | L28: =(C28-B28)/B28*100 | M28: =(D28-C28)/C28*100 | N28: =(E28-D28)/D28*100 | O28: =(F28-E28)/E28*100
A29: Итого собственный капитал | B29: 27623972 | C29: 70446792 | D29: 96984465 | E29: 207171647 | F29: 186699306 | G29: =B29/$B$29*100 | H29: =C29/$C$29*100 | I29: =D29/$D$29*100 | J29: =E29/$E$29*100 | K29: =F29/$F$29*100 | L29: =(C29-B29)/B29*100 | M29: =(D29-C29)/C29*100 | N29: =(E29-D29)/D29*100 | O29: =(F29-E29)/E29*100
A30: Долгосрочные обязательства
A31: Займы | B31: 2054936 | C31: 1925549 | D31: 0 | E31: 273582 | F31: 2509956 | G31: =B31/$B$43*100 | H31: =C31/$C$43*100 | I31: =D31/$D$43*100 | J31: =E31/$E$43*100 | K31: =F31/$F$43*100 | L31: =(C31-B31)/B31*100 | M31: =(D31-C31)/C31*100 | N31: 0 | O31: =(F31-E31)/E31*100
A32: Обязательства по аренде, долгосрочные | B32: 250676740 | C32: 265658719 | D32: 247233366 | E32: 376385720 | F32: 427807796 | G32: =B32/$B$43*100 | H32: =C32/$C$43*100 | I32: =D32/$D$43*100 | J32: =E32/$E$43*100 | K32: =F32/$F$43*100 | L32: =(C32-B32)/B32*100 | M32: =(D32-C32)/C32*100 | N32: =(E32-D32)/D32*100 | O32: =(F32-E32)/E32*100
A33: Резерв на техническое обслуживание воздушных судов | B33: 37331701 | C33: 54573269 | D33: 67555798 | E33: 152211535 | F33: 133618151 | G33: =B33/$B$43*100 | H33: =C33/$C$43*100 | I33: =D33/$D$43*100 | J33: =E33/$E$43*100 | K33: =F33/$F$43*100 | L33: =(C33-B33)/B33*100 | M33: =(D33-C33)/C33*100 | N33: =(E33-D33)/D33*100 | O33: =(F33-E33)/E33*100
A34: Вознаграждение работникам | B34: 701675 | C34: 1049290 | D34: 283191 | E34: 429540 | F34: 619780 | G34: =B34/$B$43*100 | H34: =C34/$C$43*100 | I34: =D34/$D$43*100 | J34: =E34/$E$43*100 | K34: =F34/$F$43*100 | L34: =(C34-B34)/B34*100 | M34: =(D34-C34)/C34*100 | N34: =(E34-D34)/D34*100 | O34: =(F34-E34)/E34*100
A35: Текущие обязательства
A36: Займы | B36: 24840159 | C36: 3670665 | D36: 187279 | E36: 29406 | F36: 316967 | G36: =B36/$B$43*100 | H36: =C36/$C$43*100 | I36: =D36/$D$43*100 | J36: =E36/$E$43*100 | K36: =F36/$F$43*100 | L36: =(C36-B36)/B36*100 | M36: =(D36-C36)/C36*100 | N36: =(E36-D36)/D36*100 | O36: =(F36-E36)/E36*100
A37: Обязательства по аренде | B37: 63195657 | C37: 73373051 | D37: 79546636 | E37: 90259057 | F37: 100151054 | G37: =B37/$B$43*100 | H37: =C37/$C$43*100 | I37: =D37/$D$43*100 | J37: =E37/$E$43*100 | K37: =F37/$F$43*100 | L37: =(C37-B37)/B37*100 | M37: =(D37-C37)/C37*100 | N37: =(E37-D37)/D37*100 | O37: =(F37-E37)/E37*100
A38: Доходы будущих периодов | B38: 24724868 | C38: 37082323 | D38: 38350318 | E38: 47155403 | F38: 50087407 | G38: =B38/$B$43*100 | H38: =C38/$C$43*100 | I38: =D38/$D$43*100 | J38: =E38/$E$43*100 | K38: =F38/$F$43*100 | L38: =(C38-B38)/B38*100 | M38: =(D38-C38)/C38*100 | N38: =(E38-D38)/D38*100 | O38: =(F38-E38)/E38*100
A39: Резерв на техническое обслуживание воздушных судов | B39: 17578578 | C39: 33165065 | D39: 47806075 | E39: 13269005 | F39: 69165098 | G39: =B39/$B$43*100 | H39: =C39/$C$43*100 | I39: =D39/$D$43*100 | J39: =E39/$E$43*100 | K39: =F39/$F$43*100 | L39: =(C39-B39)/B39*100 | M39: =(D39-C39)/C39*100 | N39: =(E39-D39)/D39*100 | O39: =(F39-E39)/E39*100
A40: Торговая и прочая кредиторская задолженность | B40: 27198650 | C40: 37662023 | D40: 41365415 | E40: 64878916 | F40: 62387963 | G40: =B40/$B$43*100 | H40: =C40/$C$43*100 | I40: =D40/$D$43*100 | J40: =E40/$E$43*100 | K40: =F40/$F$43*100 | L40: =(C40-B40)/B40*100 | M40: =(D40-C40)/C40*100 | N40: =(E40-D40)/D40*100 | O40: =(F40-E40)/E40*100
...

Sheet ОПиУ
A1: тыс.тенге | B1: 2021 | C1: 2022 | D1: 2023 | E1: 2024 | F1: 2025 | G1: Удельный вес 2021,% | H1: Удельный вес 2022,% | I1: Удельный вес 2023,% | J1: Удельный вес 2024,% | K1: Удельный вес 2025,% | L1: Темп прироста 2021-2022,% | M1: Темп прироста 2022-2023,% | N1: Темп прироста 2023-2024,% | O1: Темп прироста 2024-2025,%
A2: Выручка и прочие доходы
A3: Пассажирские перевозки | B3: 305252639 | C3: 462171919 | D3: 521074736 | E3: 585810042 | F3: 721046502 | G3: =B3/$B$7*100 | H3: =C3/$C$7*100 | I3: =D3/$D$7*100 | J3: =E3/$E$7*100 | K3: =F3/$F$7*100 | L3: =(C3-B3)/B3*100 | M3: =(D3-C3)/C3*100 | N3: =(E3-D3)/D3*100 | O3: =(F3-E3)/E3*100
A4: Груз и почта | B4: 14304293 | C4: 10209425 | D4: 10284481 | E4: 12413214 | F4: 14272406 | G4: =B4/$B$7*100 | H4: =C4/$C$7*100 | I4: =D4/$D$7*100 | J4: =E4/$E$7*100 | K4: =F4/$F$7*100 | L4: =(C4-B4)/B4*100 | M4: =(D4-C4)/C4*100 | N4: =(E4-D4)/D4*100 | O4: =(F4-E4)/E4*100
A5: Прочие доходы | B5: 3360585 | C5: 5600474 | D5: 3810285 | E5: 5427382 | F5: 4391707 | G5: =B5/$B$7*100 | H5: =C5/$C$7*100 | I5: =D5/$D$7*100 | J5: =E5/$E$7*100 | K5: =F5/$F$7*100 | L5: =(C5-B5)/B5*100 | M5: =(D5-C5)/C5*100 | N5: =(E5-D5)/D5*100 | O5: =(F5-E5)/E5*100
A6: Прибыль от продажи с обратной арендой | B6: 1989207 | C6: 0 | D6: 0 | E6: 12501395 | F6: 19256118 | G6: =B6/$B$7*100 | H6: =C6/$C$7*100 | I6: =D6/$D$7*100 | J6: =E6/$E$7*100 | K6: =F6/$F$7*100 | L6: =(C6-B6)/B6*100 | M6: 0 | N6: 0 | O6: =(F6-E6)/E6*100
A7: Всего выручки и прочих доходов | B7: 324906724 | C7: 477981818 | D7: 535169502 | E7: 616152033 | F7: 758966733 | G7: =B7/$B$7*100 | H7: =C7/$C$7*100 | I7: =D7/$D$7*100 | J7: =E7/$E$7*100 | K7: =F7/$F$7*100 | L7: =(C7-B7)/B7*100 | M7: =(D7-C7)/C7*100 | N7: =(E7-D7)/D7*100 | O7: =(F7-E7)/E7*100
A8: Операционные расходы
A9: Топливо | B9: -58279112 | C9: -106940565 | D9: -127357770 | E9: -143373122 | F9: -173137790 | G9: =B9/$B$7*100 | H9: =C9/$C$7*100 | I9: =D9/$D$7*100 | J9: =E9/$E$7*100 | K9: =F9/$F$7*100 | L9: =(C9-B9)/B9*100 | M9: =(D9-C9)/C9*100 | N9: =(E9-D9)/D9*100 | O9: =(F9-E9)/E9*100
A10: Расходы по персоналу и экипажу | B10: -49590527 | C10: -68827926 | D10: -88102136 | E10: -106675293 | F10: -136144112 | G10: =B10/$B$7*100 | H10: =C10/$C$7*100 | I10: =D10/$D$7*100 | J10: =E10/$E$7*100 | K10: =F10/$F$7*100 | L10: =(C10-B10)/B10*100 | M10: =(D10-C10)/C10*100 | N10: =(E10-D10)/D10*100 | O10: =(F10-E10)/E10*100
A11: Износ и амортизация | B11: -51484170 | C11: -62243853 | D11: -73944311 | E11: -88717693 | F11: -119792081 | G11: =B11/$B$7*100 | H11: =C11/$C$7*100 | I11: =D11/$D$7*100 | J11: =E11/$E$7*100 | K11: =F11/$F$7*100 | L11: =(C11-B11)/B11*100 | M11: =(D11-C11)/C11*100 | N11: =(E11-D11)/D11*100 | O11: =(F11-E11)/E11*100
A12: Инженерно-техническое обслуживание | B12: -40324060 | C12: -58228907 | D12: -49388554 | E12: -55443453 | F12: -76101528 | G12: =B12/$B$7*100 | H12: =C12/$C$7*100 | I12: =D12/$D$7*100 | J12: =E12/$E$7*100 | K12: =F12/$F$7*100 | L12: =(C12-B12)/B12*100 | M12: =(D12-C12)/C12*100 | N12: =(E12-D12)/D12*100 | O12: =(F12-E12)/E12*100
A13: Аэропортовое обслуживание и навигация | B13: -29879880 | C13: -39205987 | D13: -48241120 | E13: -56732135 | F13: -73605152 | G13: =B13/$B$7*100 | H13: =C13/$C$7*100 | I13: =D13/$D$7*100 | J13: =E13/$E$7*100 | K13: =F13/$F$7*100 | L13: =(C13-B13)/B13*100 | M13: =(D13-C13)/C13*100 | N13: =(E13-D13)/D13*100 | O13: =(F13-E13)/E13*100
A14: Обслуживание пассажиров | B14: -25961531 | C14: -37131951 | D14: -46124472 | E14: -55787727 | F14: -73426414 | G14: =B14/$B$7*100 | H14: =C14/$C$7*100 | I14: =D14/$D$7*100 | J14: =E14/$E$7*100 | K14: =F14/$F$7*100 | L14: =(C14-B14)/B14*100 | M14: =(D14-C14)/C14*100 | N14: =(E14-D14)/D14*100 | O14: =(F14-E14)/E14*100
A15: Расходы по реализации | B15: -10686310 | C15: -15334093 | D15: -18444763 | E15: -20777116 | F15: -26630517 | G15: =B15/$B$7*100 | H15: =C15/$C$7*100 | I15: =D15/$D$7*100 | J15: =E15/$E$7*100 | K15: =F15/$F$7*100 | L15: =(C15-B15)/B15*100 | M15: =(D15-C15)/C15*100 | N15: =(E15-D15)/D15*100 | O15: =(F15-E15)/E15*100
A16: Страхование | B16: -3428108 | C16: -3880892 | D16: -5011359 | E16: -6013245 | F16: -7057271 | G16: =B16/$B$7*100 | H16: =C16/$C$7*100 | I16: =D16/$D$7*100 | J16: =E16/$E$7*100 | K16: =F16/$F$7*100 | L16: =(C16-B16)/B16*100 | M16: =(D16-C16)/C16*100 | N16: =(E16-D16)/D16*100 | O16: =(F16-E16)/E16*100
A17: Информационные технологии | B17: -1951534 | C17: -2646693 | D17: -2980328 | E17: -3224735 | F17: -4203971 | G17: =B17/$B$7*100 | H17: =C17/$C$7*100 | I17: =D17/$D$7*100 | J17: =E17/$E$7*100 | K17: =F17/$F$7*100 | L17: =(C17-B17)/B17*100 | M17: =(D17-C17)/C17*100 | N17: =(E17-D17)/D17*100 | O17: =(F17-E17)/E17*100
A18: Консультационные и профессиональные услуги | B18: -1448480 | C18: -1976378 | D18: -2631258 | E18: -3874604 | F18: -3088882 | G18: =B18/$B$7*100 | H18: =C18/$C$7*100 | I18: =D18/$D$7*100 | J18: =E18/$E$7*100 | K18: =F18/$F$7*100 | L18: =(C18-B18)/B18*100 | M18: =(D18-C18)/C18*100 | N18: =(E18-D18)/D18*100 | O18: =(F18-E18)/E18*100
A19: Налоги | B19: -1066338 | C19: -677929 | D19: -1787829 | E19: -2043010 | F19: -2931190 | G19: =B19/$B$7*100 | H19: =C19/$C$7*100 | I19: =D19/$D$7*100 | J19: =E19/$E$7*100 | K19: =F19/$F$7*100 | L19: =(C19-B19)/B19*100 | M19: =(D19-C19)/C19*100 | N19: =(E19-D19)/D19*100 | O19: =(F19-E19)/E19*100
A20: Расходы по имуществу и офису | B20: -1124388 | C20: -1144309 | D20: -1766071 | E20: -2200684 | F20: -2525083 | G20: =B20/$B$7*100 | H20: =C20/$C$7*100 | I20: =D20/$D$7*100 | J20: =E20/$E$7*100 | K20: =F20/$F$7*100 | L20: =(C20-B20)/B20*100 | M20: =(D20-C20)/C20*100 | N20: =(E20-D20)/D20*100 | O20: =(F20-E20)/E20*100
A21: Переменные расходы по аренде воздушных судов | B21: -1561520 | C21: -1780324 | D21: -1000743 | E21: -2384213 | F21: -1162524 | G21: =B21/$B$7*100 | H21: =C21/$C$7*100 | I21: =D21/$D$7*100 | J21: =E21/$E$7*100 | K21: =F21/$F$7*100 | L21: =(C21-B21)/B21*100 | M21: =(D21-C21)/C21*100 | N21: =(E21-D21)/D21*100 | O21: =(F21-E21)/E21*100
A22: Убытки от обесценения дебиторской задолженности | B22: -49254 | C22: -185249 | D22: -57402 | E22: 0 | F22: 0 | G22: =B22/$B$7*100 | H22: =C22/$C$7*100 | I22: =D22/$D$7*100 | J22: =E22/$E$7*100 | K22: =F22/$F$7*100 | L22: =(C22-B22)/B22*100 | M22: =(D22-C22)/C22*100 | N22: =(E22-D22)/D22*100 | O22: 0
A23: Прочие операционные расходы | B23: -4456439 | C23: -7666288 | D23: -7045247 | E23: -6582456 | F23: -13311137 | G23: =B23/$B$7*100 | H23: =C23/$C$7*100 | I23: =D23/$D$7*100 | J23: =E23/$E$7*100 | K23: =F23/$F$7*100 | L23: =(C23-B23)/B23*100 | M23: =(D23-C23)/C23*100 | N23: =(E23-D23)/D23*100 | O23: =(F23-E23)/E23*100
A24: Всего операционные расходы | B24: -281291651 | C24: -407871344 | D24: -473883363 | E24: -553829486 | F24: -713117652 | G24: =B24/$B$7*100 | H24: =C24/$C$7*100 | I24: =D24/$D$7*100 | J24: =E24/$E$7*100 | K24: =F24/$F$7*100 | L24: =(C24-B24)/B24*100 | M24: =(D24-C24)/C24*100 | N24: =(E24-D24)/D24*100 | O24: =(F24-E24)/E24*100
A25: Операционная прибыль | B25: 43615073 | C25: 70110474 | D25: 61286139 | E25: 62322547 | F25: 45849081 | G25: =B25/$B$7*100 | H25: =C25/$C$7*100 | I25: =D25/$D$7*100 | J25: =E25/$E$7*100 | K25: =F25/$F$7*100 | L25: =(C25-B25)/B25*100 | M25: =(D25-C25)/C25*100 | N25: =(E25-D25)/D25*100 | O25: =(F25-E25)/E25*100
A26: Финансовые доходы | B26: 1026620 | C26: 3261294 | D26: 6757281 | E26: 10376957 | F26: 11633517 | G26: =B26/$B$7*100 | H26: =C26/$C$7*100 | I26: =D26/$D$7*100 | J26: =E26/$E$7*100 | K26: =F26/$F$7*100 | L26: =(C26-B26)/B26*100 | M26: =(D26-C26)/C26*100 | N26: =(E26-D26)/D26*100 | O26: =(F26-E26)/E26*100
A27: Финансовые расходы | B27: -20040053 | C27: -18073217 | D27: -22765053 | E27: -30618503 | F27: -42893475 | G27: =B27/$B$7*100 | H27: =C27/$C$7*100 | I27: =D27/$D$7*100 | J27: =E27/$E$7*100 | K27: =F27/$F$7*100 | L27: =(C27-B27)/B27*100 | M27: =(D27-C27)/C27*100 | N27: =(E27-D27)/D27*100 | O27: =(F27-E27)/E27*100
A28: Убыток от курсовой разницы, нетто | B28: -5330611 | C28: -6923638 | D28: -6280403 | E28: -9939963 | F28: -4142993 | G28: =B28/$B$7*100 | H28: =C28/$C$7*100 | I28: =D28/$D$7*100 | J28: =E28/$E$7*100 | K28: =F28/$F$7*100 | L28: =(C28-B28)/B28*100 | M28: =(D28-C28)/C28*100 | N28: =(E28-D28)/D28*100 | O28: =(F28-E28)/E28*100
A29: Прибыль до налогообложения | B29: 19271029 | C29: 48374913 | D29: 38997964 | E29: 32141038 | F29: 10446130 | G29: =B29/$B$7*100 | H29: =C29/$C$7*100 | I29: =D29/$D$7*100 | J29: =E29/$E$7*100 | K29: =F29/$F$7*100 | L29: =(C29-B29)/B29*100 | M29: =(D29-C29)/C29*100 | N29: =(E29-D29)/D29*100 | O29: =(F29-E29)/E29*100
A30: Расход по подоходному налогу | B30: -3785461 | C30: -10792015 | D30: -8258890 | E30: -6618444 | F30: -3423268 | G30: =B30/$B$7*100 | H30: =C30/$C$7*100 | I30: =D30/$D$7*100 | J30: =E30/$E$7*100 | K30: =F30/$F$7*100 | L30: =(C30-B30)/B30*100 | M30: =(D30-C30)/C30*100 | N30: =(E30-D30)/D30*100 | O30: =(F30-E30)/E30*100
A31: Прибыль за год | B31: 15485568 | C31: 37582898 | D31: 30739074 | E31: 25522594 | F31: 7022862 | G31: =B31/$B$7*100 | H31: =C31/$C$7*100 | I31: =D31/$D$7*100 | J31: =E31/$E$7*100 | K31: =F31/$F$7*100 | L31: =(C31-B31)/B31*100 | M31: =(D31-C31)/C31*100 | N31: =(E31-D31)/D31*100 | O31: =(F31-E31)/E31*100
A32: Базовая и разводненная прибыль на акцию - базовая и разводненная, тенге | B32: 910.916 | C32: 2210.759 | D32: 100.454 | E32: 73.156 | F32: 19.823 | G32: =B32/$B$7*100 | H32: =C32/$C$7*100 | I32: =D32/$D$7*100 | J32: =E32/$E$7*100 | K32: =F32/$F$7*100 | L32: =(C32-B32)/B32*100 | M32: =(D32-C32)/C32*100 | N32: =(E32-D32)/D32*100 | O32: =(F32-E32)/E32*100

Sheet ОДДС
A1: Отчет о движении денежных средств
A2: тыс. тенге
A3: Показатель | B3: 2021 | C3: 2022 | D3: 2023 | E3: 2024 | F3: 2025
A4: ОПЕРАЦИОННАЯ ДЕЯТЕЛЬНОСТЬ
A5: Прибыль до налогообложения | B5: 19271029 | C5: 48374913 | D5: 39683633 | E5: 31385844 | F5: 10503068
A6: Корректировки:
A7: Износ и амортизация основных средств и нематериальных активов | B7: 51484170 | C7: 62243853 | D7: 73820615 | E7: 89033552 | F7: 119929168
A8: Доход от выбытия основных средств | B8: -3054489 | C8: -1026474 | D8: -1594326 | E8: -12111266 | F8: -20227280
A9: Изменение резерва под обесценение дебиторской задолженности, авансов, гарантийных депозитов, денежных средств и их эквивалентов | B9: -154649 | C9: -1118045 | D9: -34630 | E9: -541249 | F9: 99706
A10: Изменение резерва на неликвидные товарно-материальные запасы | B10: -59218 | C10: 1975459 | D10: -282960 | E10: 166140 | F10: 976702
A11: Изменение в резерве отпусков | B11: 135478 | C11: -34996 | D11: -143986 | E11: 553486 | F11: 739182
A12: Изменение в резерве по техническому обслуживанию воздушных судов | B12: 25899549 | C12: 37199540 | D12: 39108600 | E12: 44852585 | F12: 56069783
A13: Изменение в резерве по программе лояльности клиентов | B13: -602832 | C13: 442982 | D13: 1263978 | E13: 1914609 | F13: -400390
A14: Убыток от курсовой разницы, нетто | B14: 5330611 | C14: 6923638 | D14: 6289363 | E14: 9762717 | F14: 4127100
A15: Финансовые доходы | B15: -763039 | C15: -2929191 | D15: -6525390 | E15: -10251724 | F15: -11631156
A16: Финансовые расходы | B16: 19931534 | C16: 18019259 | D16: 22537453 | E16: 30400300 | F16: 42929986
A17: Эффект отсрочки платежей по аренде, связанной с COVID-19 | B17: 377748 | C17: 0 | D17: 0 | E17: 0 | F17: 0
A18: Доход от досрочного возврата двигателя/воздушных судов | B18: -209440 | C18: 0 | D18: 0 | E18: -1353122 | F18: 0
... A21: Выплаты, основанные на акциях | B21: 0 | C21: 0 | D21: 0 | E21: 2875208 | F21: 487046
A22: Денежные средства, полученные от операционной деятельности до изменений в оборотном капитале | B22: =B5+B7+B8+B9+B10+B11+B12+B13+B14+B15+B16+B17+B18+B19+B20+B21 | C22: =C5+C7+C8+C9+C10+C11+C12+C13+C14+C15+C16+C17+C18+C19+C20+C21 | D22: =D5+D7+D8+D9+D10+D11+D12+D13+D14+D15+D16+D17+D18+D19+D20+D21 | E22: =E5+E7+E8+E9+E10+E11+E12+E13+E14+E15+E16+E17+E18+E19+E20+E21 | F22: =F5+F7+F8+F9+F10+F11+F12+F13+F14+F15+F16+F17+F18+F19+F20+F21
A23: Изменение торговой и прочей дебиторской задолженности | B23: -1631695 | C23: -1753047 | D23: -378647 | E23: -844348 | F23: -15610002
A24: Изменение в предоплатах и авансах выданных | B24: -2727444 | C24: 1506230 | D24: -2563042 | E24: -4801113 | F24: -10538566
A25: Изменение товарно-материальных запасов | B25: -1497495 | C25: -221491 | D25: -7649028 | E25: 770927 | F25: -11567469
A26: Изменение торговой и прочей кредиторской задолженности и резерве по техническому обслуживанию воздушных судов | B26: 1738628 | C26: -337071 | D26: -8198544 | E26: -8395476 | F26: -35710953
A27: Изменение доходов будущих периодов | B27: 8760455 | C27: 10098326 | D27: 657050 | E27: 1607274 | F27: 5243704
A28: Изменение по прочим финансовым инструментам | B28: -3147644 | C28: 2760578 | D28: -58779 | E28: 420291 | F28: 117455
A29: Денежные средства, полученные от операционной деятельности | B29: =B22+B23+B24+B25+B26+B27+B28 | C29: =C22+C23+C24+C25+C26+C27+C28 | D29: =D22+D23+D24+D25+D26+D27+D28 | E29: =E22+E23+E24+E25+E26+E27+E28 | F29: =F22+F23+F24+F25+F26+F27+F28
A30: Уплаченный подоходный налог | B30: -1707547 | C30: -21822810 | D30: -19519671 | E30: -12550855 | F30: -16566867
A31: Полученное вознаграждение | B31: 693694 | C31: 2929191 | D31: 6416034 | E31: 10233368 | F31: 11628024
A32: Чистые денежные средства, полученные от операционной деятельности | B32: =B29+B30+B31 | C32: =C29+C30+C31 | D32: =D29+D30+D31 | E32: =E29+E30+E31 | F32: =F29+F30+F31
A33: ИНВЕСТИЦИОННАЯ ДЕЯТЕЛЬНОСТЬ
A34: Приобретение основных средств | B34: -13497482 | C34: -22227370 | D34: -19035768 | E34: -46099340 | F34: -28152607
A35: Поступления от продажи с обратной арендой | B35: 3714556 | C35: 0 | D35: 0 | E35: 42593931 | F35: 72947775
A36: Поступления от продажи основных средств | B36: 1696451 | C36: 908988 | D36: 2269146 | E36: 1286760 | F36: 1868836
A37: Приобретение нематериальных активов | B37: -231449 | C37: -306179 | D37: -964159 | E37: -1735291 | F37: -749623
A38: Размещение банковских и гарантийных депозитов | B38: -1753113 | C38: -11643697 | D38: -4546950 | E38: -5988095 | F38: -29779226
A39: Погашение банковских и гарантийных депозитов | B39: 4508675 | C39: 5471423 | D39: 1310455 | E39: 1432662 | F39: 1463748
A40: Чистые денежные средства, использованные в/полученные от инвестиционной деятельности | B40: =B34+B35+B36+B37+B38+B39 | C40: =C34+C35+C36+C37+C38+C39 | D40: =D34+D35+D36+D37+D38+D39 | E40: =E34+E35+E36+E37+E38+E39 | F40: =F34+F35+F36+F37+F38+F39
A41: ФИНАНСОВАЯ ДЕЯТЕЛЬНОСТЬ
A42: Выплаты по аренде | B42: -39916368 | C42: -80533966 | D42: -78965381 | E42: -89579507 | F42: -99581823
...

Sheet Коэффициенты
A1: Коэффициент | B1: 2021 | C1: 2022 | D1: 2023 | E1: 2024 | F1: 2025
A2: Расчетная валовая маржа | B2: =(ОПиУ!B7+ОПиУ!B9+ОПиУ!B10+ОПиУ!B12+ОПиУ!B13+ОПиУ!B14)/ОПиУ!B7 | C2: =(ОПиУ!C7+ОПиУ!C9+ОПиУ!C10+ОПиУ!C12+ОПиУ!C13+ОПиУ!C14)/ОПиУ!C7 | D2: =(ОПиУ!D7+ОПиУ!D9+ОПиУ!D10+ОПиУ!D12+ОПиУ!D13+ОПиУ!D14)/ОПиУ!D7 | E2: =(ОПиУ!E7+ОПиУ!E9+ОПиУ!E10+ОПиУ!E12+ОПиУ!E13+ОПиУ!E14)/ОПиУ!E7 | F2: =(ОПиУ!F7+ОПиУ!F9+ОПиУ!F10+ОПиУ!F12+ОПиУ!F13+ОПиУ!F14)/ОПиУ!F7
A3: Операционная маржа | B3: =ОПиУ!B25/ОПиУ!B7 | C3: =ОПиУ!C25/ОПиУ!C7 | D3: =ОПиУ!D25/ОПиУ!D7 | E3: =ОПиУ!E25/ОПиУ!E7 | F3: =ОПиУ!F25/ОПиУ!F7
A4: Чистая маржа | B4: =ОПиУ!B31/ОПиУ!B7 | C4: =ОПиУ!C31/ОПиУ!C7 | D4: =ОПиУ!D31/ОПиУ!D7 | E4: =ОПиУ!E31/ОПиУ!E7 | F4: =ОПиУ!F31/ОПиУ!F7
A5: Коэффициент текущей ликвидности | B5: =(Баланс!B11+Баланс!B12+Баланс!B13+Баланс!B14+Баланс!B15+Баланс!B16+Баланс!B17+Баланс!B18)/(Баланс!B36+Баланс!B37+Баланс!B38+Баланс!B39+Баланс!B40+Баланс!B41+Баланс!B42) | C5: =(Баланс!C11+Баланс!C12+Баланс!C13+Баланс!C14+Баланс!C15+Баланс!C16+Баланс!C17+Баланс!C18)/(Баланс!C36+Баланс!C37+Баланс!C38+Баланс!C39+Баланс!C40+Баланс!C41+Баланс!C42) | D5: =(Баланс!D11+Баланс!D12+Баланс!D13+Баланс!D14+Баланс!D15+Баланс!D16+Баланс!D17+Баланс!D18)/(Баланс!D36+Баланс!D37+Баланс!D38+Баланс!D39+Баланс!D40+Баланс!D41+Баланс!D42) | E5: =(Баланс!E11+Баланс!E12+Баланс!E13+Баланс!E14+Баланс!E15+Баланс!E16+Баланс!E17+Баланс!E18)/(Баланс!E36+Баланс!E37+Баланс!E38+Баланс!E39+Баланс!E40+Баланс!E41+Баланс!E42) | F5: =(Баланс!F11+Баланс!F12+Баланс!F13+Баланс!F14+Баланс!F15+Баланс!F16+Баланс!F17+Баланс!F18)/(Баланс!F36+Баланс!F37+Баланс!F38+Баланс!F39+Баланс!F40+Баланс!F41+Баланс!F42)
A6: Коэффициент быстрой ликвидности | B6: =(Баланс!B14+Баланс!B16+Баланс!B17+Баланс!B18)/(Баланс!B36+Баланс!B37+Баланс!B38+Баланс!B39+Баланс!B40+Баланс!B41+Баланс!B42) | C6: =(Баланс!C14+Баланс!C16+Баланс!C17+Баланс!C18)/(Баланс!C36+Баланс!C37+Баланс!C38+Баланс!C39+Баланс!C40+Баланс!C41+Баланс!C42) | D6: =(Баланс!D14+Баланс!D16+Баланс!D17+Баланс!D18)/(Баланс!D36+Баланс!D37+Баланс!D38+Баланс!D39+Баланс!D40+Баланс!D41+Баланс!D42) | E6: =(Баланс!E14+Баланс!E16+Баланс!E17+Баланс!E18)/(Баланс!E36+Баланс!E37+Баланс!E38+Баланс!E39+Баланс!E40+Баланс!E41+Баланс!E42) | F6: =(Баланс!F14+Баланс!F16+Баланс!F17+Баланс!F18)/(Баланс!F36+Баланс!F37+Баланс!F38+Баланс!F39+Баланс!F40+Баланс!F41+Баланс!F42)
A7: Коэффициент абсолютной ликвидности | B7: =(Баланс!B17+Баланс!B18)/(Баланс!B36+Баланс!B37+Баланс!B38+Баланс!B39+Баланс!B40+Баланс!B41+Баланс!B42) | C7: =(Баланс!C17+Баланс!C18)/(Баланс!C36+Баланс!C37+Баланс!C38+Баланс!C39+Баланс!C40+Баланс!C41+Баланс!C42) | D7: =(Баланс!D17+Баланс!D18)/(Баланс!D36+Баланс!D37+Баланс!D38+Баланс!D39+Баланс!D40+Баланс!D41+Баланс!D42) | E7: =(Баланс!E17+Баланс!E18)/(Баланс!E36+Баланс!E37+Баланс!E38+Баланс!E39+Баланс!E40+Баланс!E41+Баланс!E42) | F7: =(Баланс!F17+Баланс!F18)/(Баланс!F36+Баланс!F37+Баланс!F38+Баланс!F39+Баланс!F40+Баланс!F41+Баланс!F42)
A8: Коэффициент автономии | B8: =Баланс!B29/Баланс!B19 | C8: =Баланс!C29/Баланс!C19 | D8: =Баланс!D29/Баланс!D19 | E8: =Баланс!E29/Баланс!E19 | F8: =Баланс!F29/Баланс!F19
A9: Коэффициент финансового левериджа | B9: =Баланс!B43/Баланс!B29 | C9: =Баланс!C43/Баланс!C29 | D9: =Баланс!D43/Баланс!D29 | E9: =Баланс!E43/Баланс!E29 | F9: =Баланс!F43/Баланс!F29
A10: Покрытие финансовых расходов | B10: =ОПиУ!B25/(-ОПиУ!B27) | C10: =ОПиУ!C25/(-ОПиУ!C27) | D10: =ОПиУ!D25/(-ОПиУ!D27) | E10: =ОПиУ!E25/(-ОПиУ!E27) | F10: =ОПиУ!F25/(-ОПиУ!F27)
A11: Чистый оборотный капитал, тыс. тг | B11: =(Баланс!B11+Баланс!B12+Баланс!B13+Баланс!B14+Баланс!B15+Баланс!B16+Баланс!B17+Баланс!B18)-(Баланс!B36+Баланс!B37+Баланс!B38+Баланс!B39+Баланс!B40+Баланс!B41+Баланс!B42) | C11: =(Баланс!C11+Баланс!C12+Баланс!C13+Баланс!C14+Баланс!C15+Баланс!C16+Баланс!C17+Баланс!C18)-(Баланс!C36+Баланс!C37+Баланс!C38+Баланс!C39+Баланс!C40+Баланс!C41+Баланс!C42) | D11: =(Баланс!D11+Баланс!D12+Баланс!D13+Баланс!D14+Баланс!D15+Баланс!D16+Баланс!D17+Баланс!D18)-(Баланс!D36+Баланс!D37+Баланс!D38+Баланс!D39+Баланс!D40+Баланс!D41+Баланс!D42) | E11: =(Баланс!E11+Баланс!E12+Баланс!E13+Баланс!E14+Баланс!E15+Баланс!E16+Баланс!E17+Баланс!E18)-(Баланс!E36+Баланс!E37+Баланс!E38+Баланс!E39+Баланс!E40+Баланс!E41+Баланс!E42) | F11: =(Баланс!F11+Баланс!F12+Баланс!F13+Баланс!F14+Баланс!F15+Баланс!F16+Баланс!F17+Баланс!F18)-(Баланс!F36+Баланс!F37+Баланс!F38+Баланс!F39+Баланс!F40+Баланс!F41+Баланс!F42)

Sheet Инпут
A1: Год | B1: Компания | C1: Валюта | D1: Масштаб | E1: Источник | F1: Выручка всего | G1: Операционная прибыль | H1: Чистая прибыль | I1: Активы всего | J1: Обязательства всего | K1: Капитал | L1: Денежные средства | M1: Дебиторская задолженность | N1: Запасы | O1: Основные средства | P1: Нематериальные активы | Q1: Займы всего | R1: Обязательства по аренде всего | S1: Итого долг | T1: CFO | U1: CFI | V1: CFF | W1: Capex | X1: Операционная маржа | Y1: Чистая маржа | Z1: ROA | AA1: ROE | AB1: Долг / Активы | AC1: Долг / Капитал | AD1: CFO / чистая прибыль | AE1: FCF
A2: 2021 | B2: Air Astana | C2: KZT | D2: тыс. тенге | E2: Финансовая отчетность Air Astana; листы Баланс и ОДДС,ОПиУ | F2: =ОПиУ!B7 | G2: =ОПиУ!B25 | H2: =ОПиУ!B31 | I2: =Баланс!B19 | J2: =Баланс!B43 | K2: =Баланс!B29 | L2: =Баланс!B17 | M2: =Баланс!B14 | N2: =Баланс!B11 | O2: =Баланс!B4 | P2: =Баланс!B5 | Q2: =Баланс!B31+Баланс!B36 | R2: =Баланс!B32+Баланс!B37 | S2: =Q2+R2 | T2: =ОДДС!B32 | U2: =ОДДС!B40 | V2: =ОДДС!B50 | W2: =ОДДС!B58 | X2: =G2/F2 | Y2: =H2/F2 | Z2: =H2/I2 | AA2: =H2/K2 | AB2: =S2/I2 | AC2: =S2/K2 | AD2: =T2/H2 | AE2: =T2-W2
A3: 2022 | B3: Air Astana | C3: KZT | D3: тыс. тенге | E3: Финансовая отчетность Air Astana; листы Баланс и ОДДС,ОПиУ | F3: =ОПиУ!C7 | G3: =ОПиУ!C25 | H3: =ОПиУ!C31 | I3: =Баланс!C19 | J3: =Баланс!C43 | K3: =Баланс!C29 | L3: =Баланс!C17 | M3: =Баланс!C14 | N3: =Баланс!C11 | O3: =Баланс!C4 | P3: =Баланс!C5 | Q3: =Баланс!C31+Баланс!C36 | R3: =Баланс!C32+Баланс!C37 | S3: =Q3+R3 | T3: =ОДДС!C32 | U3: =ОДДС!C40 | V3: =ОДДС!C50 | W3: =ОДДС!C58 | X3: =G3/F3 | Y3: =H3/F3 | Z3: =H3/I3 | AA3: =H3/K3 | AB3: =S3/I3 | AC3: =S3/K3 | AD3: =T3/H3 | AE3: =T3-W3
A4: 2023 | B4: Air Astana | C4: KZT | D4: тыс. тенге | E4: Финансовая отчетность Air Astana; листы Баланс и ОДДС,ОПиУ | F4: =ОПиУ!D7 | G4: =ОПиУ!D25 | H4: =ОПиУ!D31 | I4: =Баланс!D19 | J4: =Баланс!D43 | K4: =Баланс!D29 | L4: =Баланс!D17 | M4: =Баланс!D14 | N4: =Баланс!D11 | O4: =Баланс!D4 | P4: =Баланс!D5 | Q4: =Баланс!D31+Баланс!D36 | R4: =Баланс!D32+Баланс!D37 | S4: =Q4+R4 | T4: =ОДДС!D32 | U4: =ОДДС!D40 | V4: =ОДДС!D50 | W4: =ОДДС!D58 | X4: =G4/F4 | Y4: =H4/F4 | Z4: =H4/I4 | AA4: =H4/K4 | AB4: =S4/I4 | AC4: =S4/K4 | AD4: =T4/H4 | AE4: =T4-W4
A5: 2024 | B5: Air Astana | C5: KZT | D5: тыс. тенге | E5: Финансовая отчетность Air Astana; листы Баланс и ОДДС,ОПиУ | F5: =ОПиУ!E7 | G5: =ОПиУ!E25 | H5: =ОПиУ!E31 | I5: =Баланс!E19 | J5: =Баланс!E43 | K5: =Баланс!E29 | L5: =Баланс!E17 | M5: =Баланс!E14 | N5: =Баланс!E11 | O5: =Баланс!E4 | P5: =Баланс!E5 | Q5: =Баланс!E31+Баланс!E36 | R5: =Баланс!E32+Баланс!E37 | S5: =Q5+R5 | T5: =ОДДС!E32 | U5: =ОДДС!E40 | V5: =ОДДС!E50 | W5: =ОДДС!E58 | X5: =G5/F5 | Y5: =H5/F5 | Z5: =H5/I5 | AA5: =H5/K5 | AB5: =S5/I5 | AC5: =S5/K5 | AD5: =T5/H5 | AE5: =T5-W5
A6: 2025 | B6: Air Astana | C6: KZT | D6: тыс. тенге | E6: Финансовая отчетность Air Astana; листы Баланс и ОДДС,ОПиУ | F6: =ОПиУ!F7 | G6: =ОПиУ!F25 | H6: =ОПиУ!F31 | I6: =Баланс!F19 | J6: =Баланс!F43 | K6: =Баланс!F29 | L6: =Баланс!F17 | M6: =Баланс!F14 | N6: =Баланс!F11 | O6: =Баланс!F4 | P6: =Баланс!F5 | Q6: =Баланс!F31+Баланс!F36 | R6: =Баланс!F32+Баланс!F37 | S6: =Q6+R6 | T6: =ОДДС!F32 | U6: =ОДДС!F40 | V6: =ОДДС!F50 | W6: =ОДДС!F58 | X6: =G6/F6 | Y6: =H6/F6 | Z6: =H6/I6 | AA6: =H6/K6 | AB6: =S6/I6 | AC6: =S6/K6 | AD6: =T6/H6 | AE6: =T6-W6

Sheet Проверки
A1: Проверка | B1: 2021 | C1: 2022 | D1: 2023 | E1: 2024 | F1: 2025
A2: Баланс сходится | B2: =Инпут!I2-Инпут!J2-Инпут!K2 | C2: =Инпут!I3-Инпут!J3-Инпут!K3 | D2: =Инпут!I4-Инпут!J4-Инпут!K4 | E2: =Инпут!I5-Инпут!J5-Инпут!K5 | F2: =Инпут!I6-Инпут!J6-Инпут!K6
A3: Валюта | B3: =Инпут!C2 | C3: =Инпут!C3 | D3: =Инпут!C4 | E3: =Инпут!C5 | F3: =Инпут!C6
A4: Масштаб | B4: =Инпут!D2 | C4: =Инпут!D3 | D4: =Инпут!D4 | E4: =Инпут!D5 | F4: =Инпут!D6
A5: CFO | B5: =Инпут!T2 | C5: =Инпут!T3 | D5: =Инпут!T4 | E5: =Инпут!T5 | F5: =Инпут!T6
A6: FCF | B6: =Инпут!T2-Инпут!W2 | C6: =Инпут!T3-Инпут!W3 | D6: =Инпут!T4-Инпут!W4 | E6: =Инпут!T5-Инпут!W5 | F6: =Инпут!T6-Инпут!W6

Sheet Источники
A1: Год | B1: Документ | C1: Файл / ссылка | D1: Комментарий для сдачи
A2: 2021 | B2: Финансовая отчетность Air Astana за 2021 год | C2: C:/Users/malin/Downloads/финансовая_отчетность-_за_2021_год.pdf | D2: Для GitHub лучше добавить публичный URL или приложить PDF в data/sources.
A3: 2022 | B3: Финансовая отчетность Air Astana за 2022 год | C3: C:/Users/malin/Downloads/fs_aa_kzt_2022_signed.pdf | D3: Для GitHub лучше добавить публичный URL или приложить PDF в data/sources.
A4: 2023-2025 | B4: Исходный Excel с анализом | C4: C:/Users/malin/Downloads/ЭйрАстана.xlsx | D4: Проверь валюту исходного файла: Input приведен в KZT, тыс. тенге.
A5: 2021-2022 | B5: Полный ОДДС | C5: Финансовая отчетность Air Astana за 2021-2022 годы | D5: Используется для полного ОДДС.
A6: 2023 | B6: Полный ОДДС | C6: https://ir.airastana.com/media/8dc44aa8f61bda7/aa-fs-2023-conso-usd.pdf | D6: Проверь, что значения приведены к KZT, если ссылка на USD-отчет.
A7: 2024 | B7: Полный ОДДС | C7: https://ir.airastana.com/media/8dd62d1cc357574/fs-aa-usd-2024-conso-eng-final-signed.pdf | D7: Проверь, что значения приведены к KZT, если ссылка на USD-отчет.
A8: 2025 | B8: Полный ОДДС | C8: https://ir.airastana.com/media/8de832fbd001d0b/fs-aa-usd-2025-eng-final-formatted-signed-final.pdf | D8: Проверь, что значения приведены к KZT, если ссылка на USD-отчет.

Sheet Data_Dictionary
A1: Поле / группа полей | B1: Статус по ТЗ | C1: Что означает | D1: Источник / расчет
A2: Год, Компания, Период анализа | B2: Обязательно | C2: Идентификация компании и периода анализа | D2: Заполняется в Input_Complete
A3: Валюта, Масштаб | B3: Обязательно | C3: Единая валюта и единицы измерения | D3: KZT, тыс. тенге; проверяется в Checks_Complete
A4: Источник, Notes/MD&A | B4: Обязательно | C4: Откуда взяты ключевые цифры и раскрытия | D4: Лист Источники + годовые отчеты
A5: Выручка всего | B5: Обязательно | C5: Всего выручки и прочих доходов | D5: ОПиУ строка 7
A6: Себестоимость / прямые операционные расходы | B6: Обязательно, адаптировано | C6: Расчетная себестоимость для авиакомпании | D6: ОПиУ строки 9, 10, 12, 13, 14
A7: Валовая прибыль расчетная | B7: Если применимо | C7: Расчетная прибыль после прямых операционных расходов | D7: Выручка + прямые расходы
A8: Операционная прибыль, фин. доходы/расходы, налог, чистая прибыль | B8: Обязательно | C8: Основные строки ОПиУ | D8: ОПиУ строки 25, 26, 27, 30, 31
A9: Активы, деньги, дебиторка, запасы, ОС, НМА | B9: Обязательно | C9: Основные строки активов | D9: Баланс
A10: Обязательства, займы, аренда, капитал | B10: Обязательно | C10: Структура финансирования и долга | D10: Баланс
A11: CFO, CFI, CFF, Capex, дивиденды | B11: Обязательно | C11: Денежные потоки, инвестиции и выплаты акционерам | D11: ОДДС строки 32, 40, 50, 34, 49
A12: Коэффициенты и отраслевые метрики | B12: Для блоков 2-4 | C12: Готовые признаки для анализа, качества и прогноза | D12: Расчет из нормализованных строк

Sheet Limitations
A1: Раздел | B1: Текст для методологии / приложения
A2: Ограничение по валовой прибыли | B2: Air Astana раскрывает операционные расходы по статьям, но не отдельную классическую себестоимость продаж. Поэтому для Input используется расчетная валовая прибыль на основе ключевых прямых расходов авиакомпании: топливо, персонал и экипаж, техническое обслуживание, аэропортовое обслуживание и обслуживание пассажиров.
A3: Ограничение по источникам | B3: Каждая ключевая цифра связана с финансовой отчетностью соответствующего года. Для финальной сдачи желательно заменить локальные пути на публичные URL или приложить файлы отчетности в data/sources.
A4: Ограничение по валюте | B4: Input приведен в KZT, тыс. тенге. Если отдельные исходные отчеты за 2023-2025 использовались в USD, в методологии нужно явно описать пересчет или заменить источник на KZT-версию отчетности.
A5: Назначение файла | B5: Лист Input_Complete является основным sample input file для приложения. Остальные листы сохраняют исходные расшифровки и проверки.
A6: Что закрывает блок 1 | B6: Файл показывает компанию, период, источники, основные financial statements за 5 лет, нормализованные строки, валюту/масштаб и базовую арифметику.
