Workbook

Sheet Баланс
A1: тыс. тенге | B1: 2021 | C1: 2022 | D1: 2023 | E1: 2024 | F1: 2025 | G1: Удельный вес 2021,% | H1: Удельный вес 2022,% | I1: Удельный вес 2023,% | J1: Удельный вес 2024,% | K1: Удельный вес 2025,% | L1: Темп прироста 2021-2022,% | M1: Темп прироста 2022-2023,% | N1: Темп прироста 2023-2024,% | O1: Темп прироста 2024-2025,%
A2: Активы
A3: Долгосрочные активы
A4: Основные средства | B4: 311845960 | C4: 378255700 | D4: 387885139 | E4: 558341061 | F4: 604500136 | G4: =B4/$B$19*100 -> 65.523915 | H4: =C4/$C$19*100 -> 65.361047 | I4: =D4/$D$19*100 -> 62.631565 | J4: =E4/$E$19*100 -> 58.64534 | K4: =F4/$F$19*100 -> 58.143832 | L4: =(C4-B4)/B4*100 -> 21.295687 | M4: =(D4-C4)/C4*100 -> 2.5457486 | N4: =(E4-D4)/D4*100 -> 43.944948 | O4: =(F4-E4)/E4*100 -> 8.2671826
A5: Нематериальные активы | B5: 659790 | C5: 718495 | D5: 1289132 | E5: 3160112 | F5: 3286956 | G5: =B5/$B$19*100 -> 0.13863262 | H5: =C5/$C$19*100 -> 0.12415302 | I5: =D5/$D$19*100 -> 0.20815532 | J5: =E5/$E$19*100 -> 0.33192229 | K5: =F5/$F$19*100 -> 0.31615579 | L5: =(C5-B5)/B5*100 -> 8.897528 | M5: =(D5-C5)/C5*100 -> 79.421151 | N5: =(E5-D5)/D5*100 -> 145.13487 | O5: =(F5-E5)/E5*100 -> 4.0139084
A6: Авансы выданные | B6: 7037908 | C6: 7178940 | D6: 8387087 | E6: 10287430 | F6: 10275403 | G6: =B6/$B$19*100 -> 1.4787791 | H6: =C6/$C$19*100 -> 1.2404916 | I6: =D6/$D$19*100 -> 1.3542576 | J6: =E6/$E$19*100 -> 1.08054 | K6: =F6/$F$19*100 -> 0.98833941 | L6: =(C6-B6)/B6*100 -> 2.0038909 | M6: =(D6-C6)/C6*100 -> 16.829044 | N6: =(E6-D6)/D6*100 -> 22.657962 | O6: =(F6-E6)/E6*100 -> -0.11690967
A7: Гарантийные депозиты | B7: 7761173 | C7: 13657428 | D7: 15137757 | E7: 20319131 | F7: 22723574 | G7: =B7/$B$19*100 -> 1.6307488 | H7: =C7/$C$19*100 -> 2.359948 | I7: =D7/$D$19*100 -> 2.4442839 | J7: =E7/$E$19*100 -> 2.1342194 | K7: =F7/$F$19*100 -> 2.1856665 | L7: =(C7-B7)/B7*100 -> 75.971184 | M7: =(D7-C7)/C7*100 -> 10.839003 | N7: =(E7-D7)/D7*100 -> 34.228149 | O7: =(F7-E7)/E7*100 -> 11.833395
A8: Отложенные налоговые активы | B8: 1170610 | C8: 8553011 | D8: 16836902 | E8: 25521921 | F8: 40910015 | G8: =B8/$B$19*100 -> 0.24596423 | H8: =C8/$C$19*100 -> 1.4779255 | I8: =D8/$D$19*100 -> 2.7186438 | J8: =E8/$E$19*100 -> 2.6806944 | K8: =F8/$F$19*100 -> 3.9349289 | L8: =(C8-B8)/B8*100 -> 630.64565 | M8: =(D8-C8)/C8*100 -> 96.853506 | N8: =(E8-D8)/D8*100 -> 51.583237 | O8: =(F8-E8)/E8*100 -> 60.293635
A9: Торговая и прочая дебиторская задолженность | B9: 1559230 | C9: 601445 | D9: 610474 | E9: 330819 | F9: 839685 | G9: =B9/$B$19*100 -> 0.32761962 | H9: =C9/$C$19*100 -> 0.10392725 | I9: =D9/$D$19*100 -> 0.098572846 | J9: =E9/$E$19*100 -> 0.034747566 | K9: =F9/$F$19*100 -> 0.080765083 | L9: =(C9-B9)/B9*100 -> -61.426794 | M9: =(D9-C9)/C9*100 -> 1.5012179 | N9: =(E9-D9)/D9*100 -> -45.809486 | O9: =(F9-E9)/E9*100 -> 153.82006
A10: Текущие активы
A11: Товарно-материальные запасы | B11: 22261449 | C11: 22750814 | D11: 30704619 | E11: 34724999 | F11: 43686386 | G11: =B11/$B$19*100 -> 4.677493 | H11: =C11/$C$19*100 -> 3.9312482 | I11: =D11/$D$19*100 -> 4.9578552 | J11: =E11/$E$19*100 -> 3.6473395 | K11: =F11/$F$19*100 -> 4.2019741 | L11: =(C11-B11)/B11*100 -> 2.1982621 | M11: =(D11-C11)/C11*100 -> 34.960529 | N11: =(E11-D11)/D11*100 -> 13.09373 | O11: =(F11-E11)/E11*100 -> 25.806731
A12: Авансы выданные, текущие | B12: 11457381 | C12: 9720739 | D12: 11284452 | E12: 15905582 | F12: 15880719 | G12: =B12/$B$19*100 -> 2.4073823 | H12: =C12/$C$19*100 -> 1.6797042 | I12: =D12/$D$19*100 -> 1.8220932 | J12: =E12/$E$19*100 -> 1.6706424 | K12: =F12/$F$19*100 -> 1.5274866 | L12: =(C12-B12)/B12*100 -> -15.157408 | M12: =(D12-C12)/C12*100 -> 16.086359 | N12: =(E12-D12)/D12*100 -> 40.951302 | O12: =(F12-E12)/E12*100 -> -0.15631619
A13: Предоплата по подоходному налогу | B13: 1135634 | C13: 4153672 | D13: 6027011 | E13: 6825905 | F13: 3591791 | G13: =B13/$B$19*100 -> 0.2386152 | H13: =C13/$C$19*100 -> 0.71773764 | I13: =D13/$D$19*100 -> 0.97317761 | J13: =E13/$E$19*100 -> 0.71695877 | K13: =F13/$F$19*100 -> 0.34547634 | L13: =(C13-B13)/B13*100 -> 265.75798 | M13: =(D13-C13)/C13*100 -> 45.100793 | N13: =(E13-D13)/D13*100 -> 13.255227 | O13: =(F13-E13)/E13*100 -> -47.380003
A14: Торговая и прочая дебиторская задолженность | B14: 6103061 | C14: 9857684 | D14: 10693524 | E14: 10922813 | F14: 13142263 | G14: =B14/$B$19*100 -> 1.2823525 | H14: =C14/$C$19*100 -> 1.7033677 | I14: =D14/$D$19*100 -> 1.7266765 | J14: =E14/$E$19*100 -> 1.1472774 | K14: =F14/$F$19*100 -> 1.2640883 | L14: =(C14-B14)/B14*100 -> 61.520326 | M14: =(D14-C14)/C14*100 -> 8.4790707 | N14: =(E14-D14)/D14*100 -> 2.1441856 | O14: =(F14-E14)/E14*100 -> 20.319399
A15: Предоплата по прочим налогам | B15: 3328746 | C15: 3876082 | D15: 4657876 | E15: 7242317 | F15: 16126407 | G15: =B15/$B$19*100 -> 0.69942375 | H15: =C15/$C$19*100 -> 0.66977121 | I15: =D15/$D$19*100 -> 0.75210426 | J15: =E15/$E$19*100 -> 0.7606966 | K15: =F15/$F$19*100 -> 1.5511181 | L15: =(C15-B15)/B15*100 -> 16.442708 | M15: =(D15-C15)/C15*100 -> 20.169697 | N15: =(E15-D15)/D15*100 -> 55.485397 | O15: =(F15-E15)/E15*100 -> 122.66917
A16: Гарантийные депозиты, текущие | B16: 677062 | C16: 1626677 | D16: 899574 | E16: 1700831 | F16: 25524210 | G16: =B16/$B$19*100 -> 0.14226175 | H16: =C16/$C$19*100 -> 0.28108317 | I16: =D16/$D$19*100 -> 0.14525364 | J16: =E16/$E$19*100 -> 0.17864674 | K16: =F16/$F$19*100 -> 2.4550456 | L16: =(C16-B16)/B16*100 -> 140.25525 | M16: =(D16-C16)/C16*100 -> -44.698671 | N16: =(E16-D16)/D16*100 -> 89.070716 | O16: =(F16-E16)/E16*100 -> 1400.6905
A17: Денежные средства и их эквиваленты | B17: 97740953 | C17: 116998633 | D17: 124552167 | E17: 256622307 | F17: 239053004 | G17: =B17/$B$19*100 -> 20.536966 | H17: =C17/$C$19*100 -> 20.216888 | I17: =D17/$D$19*100 -> 20.111359 | J17: =E17/$E$19*100 -> 26.954318 | K17: =F17/$F$19*100 -> 22.993308 | L17: =(C17-B17)/B17*100 -> 19.702775 | M17: =(D17-C17)/C17*100 -> 6.4560874 | N17: =(E17-D17)/D17*100 -> 106.036 | O17: =(F17-E17)/E17*100 -> -6.8463662
A18: Прочие финансовые активы | B18: 3187979 | C18: 767999 | D18: 346829 | E18: 158583 | F18: 122844 | G18: =B18/$B$19*100 -> 0.66984631 | H18: =C18/$C$19*100 -> 0.1327071 | I18: =D18/$D$19*100 -> 0.056002257 | J18: =E18/$E$19*100 -> 0.016656762 | K18: =F18/$F$19*100 -> 0.011815747 | L18: =(C18-B18)/B18*100 -> -75.909534 | M18: =(D18-C18)/C18*100 -> -54.839915 | N18: =(E18-D18)/D18*100 -> -54.276315 | O18: =(F18-E18)/E18*100 -> -22.536464
A19: Итого активы | B19: 475926936 | C19: 578717319 | D19: 619312543 | E19: 952063811 | F19: 1039663393 | G19: =B19/$B$19*100 -> 100 | H19: =C19/$C$19*100 -> 100 | I19: =D19/$D$19*100 -> 100 | J19: =E19/$E$19*100 -> 100 | K19: =F19/$F$19*100 -> 100 | L19: =(C19-B19)/B19*100 -> 21.597933 | M19: =(D19-C19)/C19*100 -> 7.0146897 | N19: =(E19-D19)/D19*100 -> 53.729134 | O19: =(F19-E19)/E19*100 -> 9.20102
A20: Собственный капитал и обязательства
A21: Собственный капитал
A22: Акционерный капитал | B22: 2501550 | C22: 2501550 | D22: 2501550 | E22: 56758223 | F22: 56758223 | G22: =B22/$B$29*100 -> 9.0557216 | H22: =C22/$C$29*100 -> 3.5509779 | I22: =D22/$D$29*100 -> 2.5793306 | J22: =E22/$E$29*100 -> 27.396714 | K22: =F22/$F$29*100 -> 30.400875 | L22: =(C22-B22)/B22*100 -> 0 | M22: =(D22-C22)/C22*100 -> 0 | N22: =(E22-D22)/D22*100 -> 2168.9222 | O22: =(F22-E22)/E22*100 -> 0
A23: Дополнительно оплаченный капитал | B23: 48996 | C23: 48996 | D23: 48996 | E23: 48996 | F23: 48996 | G23: =B23/$B$29*100 -> 0.17736769 | H23: =C23/$C$29*100 -> 0.069550364 | I23: =D23/$D$29*100 -> 0.050519431 | J23: =E23/$E$29*100 -> 0.023649954 | K23: =F23/$F$29*100 -> 0.026243268 | L23: =(C23-B23)/B23*100 -> 0 | M23: =(D23-C23)/C23*100 -> 0 | N23: =(E23-D23)/D23*100 -> 0 | O23: =(F23-E23)/E23*100 -> 0
A24: Прочие резервы | B24: 0 | C24: 0 | D24: 0 | E24: 1455281 | F24: -691711 | G24: =B24/$B$29*100 -> 0 | H24: =C24/$C$29*100 -> 0 | I24: =D24/$D$29*100 -> 0 | J24: =E24/$E$29*100 -> 0.70245182 | K24: =F24/$F$29*100 -> -0.37049468 | L24: 0 | M24: 0 | N24: 0 | O24: =(F24-E24)/E24*100 -> -147.5311
A25: Выкупленные акции | B25: 0 | C25: 0 | D25: 0 | E25: -3952306 | F25: -2624585 | G25: =B25/$B$29*100 -> 0 | H25: =C25/$C$29*100 -> 0 | I25: =D25/$D$29*100 -> 0 | J25: =E25/$E$29*100 -> -1.9077446 | K25: =F25/$F$29*100 -> -1.4057819 | L25: 0 | M25: 0 | N25: 0 | O25: =(F25-E25)/E25*100 -> -33.593578
A26: Резерв по пересчету валюты отчетности | B26: 10002799 | C26: 11930890 | D26: 12323792 | E26: 40842148 | F26: 34332765 | G26: =B26/$B$29*100 -> 36.210575 | H26: =C26/$C$29*100 -> 16.93603 | I26: =D26/$D$29*100 -> 12.706975 | J26: =E26/$E$29*100 -> 19.714159 | K26: =F26/$F$29*100 -> 18.389337 | L26: =(C26-B26)/B26*100 -> 19.275515 | M26: =(D26-C26)/C26*100 -> 3.2931491 | N26: =(E26-D26)/D26*100 -> 231.40894 | O26: =(F26-E26)/E26*100 -> -15.937906
A27: Резерв по инструментам хеджирования, за вычетом налога | B27: -11723938 | C27: -8412107 | D27: -5489830 | E27: -1965955 | F27: -60737 | G27: =B27/$B$29*100 -> -42.441174 | H27: =C27/$C$29*100 -> -11.941079 | I27: =D27/$D$29*100 -> -5.6605251 | J27: =E27/$E$29*100 -> -0.94894983 | K27: =F27/$F$29*100 -> -0.03253199 | L27: =(C27-B27)/B27*100 -> -28.248452 | M27: =(D27-C27)/C27*100 -> -34.738942 | N27: =(E27-D27)/D27*100 -> -64.189146 | O27: =(F27-E27)/E27*100 -> -96.91056
A28: Нераспределенная прибыль | B28: 26749565 | C28: 64377463 | D28: 87599957 | E28: 113985260 | F28: 98936355 | G28: =B28/$B$29*100 -> 96.834608 | H28: =C28/$C$29*100 -> 91.38452 | I28: =D28/$D$29*100 -> 90.3237 | J28: =E28/$E$29*100 -> 55.01972 | K28: =F28/$F$29*100 -> 52.992353 | L28: =(C28-B28)/B28*100 -> 140.66733 | M28: =(D28-C28)/C28*100 -> 36.072397 | N28: =(E28-D28)/D28*100 -> 30.120224 | O28: =(F28-E28)/E28*100 -> -13.202501
A29: Итого собственный капитал | B29: 27623972 | C29: 70446792 | D29: 96984465 | E29: 207171647 | F29: 186699306 | G29: =B29/$B$29*100 -> 100 | H29: =C29/$C$29*100 -> 100 | I29: =D29/$D$29*100 -> 100 | J29: =E29/$E$29*100 -> 100 | K29: =F29/$F$29*100 -> 100 | L29: =(C29-B29)/B29*100 -> 155.0205 | M29: =(D29-C29)/C29*100 -> 37.67052 | N29: =(E29-D29)/D29*100 -> 113.61323 | O29: =(F29-E29)/E29*100 -> -9.8818257
A30: Долгосрочные обязательства
A31: Займы | B31: 2054936 | C31: 1925549 | D31: 0 | E31: 273582 | F31: 2509956 | G31: =B31/$B$43*100 -> 0.45838109 | H31: =C31/$C$43*100 -> 0.37884333 | I31: =D31/$D$43*100 -> 0 | J31: =E31/$E$43*100 -> 0.036727732 | K31: =F31/$F$43*100 -> 0.2942628 | L31: =(C31-B31)/B31*100 -> -6.2964005 | M31: =(D31-C31)/C31*100 -> -100 | N31: 0 | O31: =(F31-E31)/E31*100 -> 817.44194
A32: Обязательства по аренде, долгосрочные | B32: 250676740 | C32: 265658719 | D32: 247233366 | E32: 376385720 | F32: 427807796 | G32: =B32/$B$43*100 -> 55.916815 | H32: =C32/$C$43*100 -> 52.267189 | I32: =D32/$D$43*100 -> 47.332965 | J32: =E32/$E$43*100 -> 50.528887 | K32: =F32/$F$43*100 -> 50.155429 | L32: =(C32-B32)/B32*100 -> 5.9766131 | M32: =(D32-C32)/C32*100 -> -6.935723 | N32: =(E32-D32)/D32*100 -> 52.239047 | O32: =(F32-E32)/E32*100 -> 13.662069
A33: Резерв на техническое обслуживание воздушных судов | B33: 37331701 | C33: 54573269 | D33: 67555798 | E33: 152211535 | F33: 133618151 | G33: =B33/$B$43*100 -> 8.3273375 | H33: =C33/$C$43*100 -> 10.737052 | I33: =D33/$D$43*100 -> 12.933595 | J33: =E33/$E$43*100 -> 20.434036 | K33: =F33/$F$43*100 -> 15.665156 | L33: =(C33-B33)/B33*100 -> 46.184791 | M33: =(D33-C33)/C33*100 -> 23.789172 | N33: =(E33-D33)/D33*100 -> 125.31232 | O33: =(F33-E33)/E33*100 -> -12.215489
A34: Вознаграждение работникам | B34: 701675 | C34: 1049290 | D34: 283191 | E34: 429540 | F34: 619780 | G34: =B34/$B$43*100 -> 0.15651804 | H34: =C34/$C$43*100 -> 0.20644321 | I34: =D34/$D$43*100 -> 0.054217074 | J34: =E34/$E$43*100 -> 0.057664723 | K34: =F34/$F$43*100 -> 0.07266191 | L34: =(C34-B34)/B34*100 -> 49.540742 | M34: =(D34-C34)/C34*100 -> -73.011179 | N34: =(E34-D34)/D34*100 -> 51.678549 | O34: =(F34-E34)/E34*100 -> 44.28924
A35: Текущие обязательства
A36: Займы | B36: 24840159 | C36: 3670665 | D36: 187279 | E36: 29406 | F36: 316967 | G36: =B36/$B$43*100 -> 5.5409312 | H36: =C36/$C$43*100 -> 0.72218726 | I36: =D36/$D$43*100 -> 0.035854668 | J36: =E36/$E$43*100 -> 0.0039476855 | K36: =F36/$F$43*100 -> 0.03716065 | L36: =(C36-B36)/B36*100 -> -85.22286 | M36: =(D36-C36)/C36*100 -> -94.897954 | N36: =(E36-D36)/D36*100 -> -84.298293 | O36: =(F36-E36)/E36*100 -> 977.89907
A37: Обязательства по аренде | B37: 63195657 | C37: 73373051 | D37: 79546636 | E37: 90259057 | F37: 100151054 | G37: =B37/$B$43*100 -> 14.09664 | H37: =C37/$C$43*100 -> 14.435826 | I37: =D37/$D$43*100 -> 15.229248 | J37: =E37/$E$43*100 -> 12.117064 | K37: =F37/$F$43*100 -> 11.741532 | L37: =(C37-B37)/B37*100 -> 16.104578 | M37: =(D37-C37)/C37*100 -> 8.413968 | N37: =(E37-D37)/D37*100 -> 13.466844 | O37: =(F37-E37)/E37*100 -> 10.959562
A38: Доходы будущих периодов | B38: 24724868 | C38: 37082323 | D38: 38350318 | E38: 47155403 | F38: 50087407 | G38: =B38/$B$43*100 -> 5.515214 | H38: =C38/$C$43*100 -> 7.2957846 | I38: =D38/$D$43*100 -> 7.3421896 | J38: =E38/$E$43*100 -> 6.3305006 | K38: =F38/$F$43*100 -> 5.872159 | L38: =(C38-B38)/B38*100 -> 49.979862 | M38: =(D38-C38)/C38*100 -> 3.4194055 | N38: =(E38-D38)/D38*100 -> 22.959614 | O38: =(F38-E38)/E38*100 -> 6.2177477
A39: Резерв на техническое обслуживание воздушных судов | B39: 17578578 | C39: 33165065 | D39: 47806075 | E39: 13269005 | F39: 69165098 | G39: =B39/$B$43*100 -> 3.921138 | H39: =C39/$C$43*100 -> 6.5250813 | I39: =D39/$D$43*100 -> 9.1524996 | J39: =E39/$E$43*100 -> 1.7813323 | K39: =F39/$F$43*100 -> 8.1087937 | L39: =(C39-B39)/B39*100 -> 88.667508 | M39: =(D39-C39)/C39*100 -> 44.145881 | N39: =(E39-D39)/D39*100 -> -72.244103 | O39: =(F39-E39)/E39*100 -> 421.25309
A40: Торговая и прочая кредиторская задолженность | B40: 27198650 | C40: 37662023 | D40: 41365415 | E40: 64878916 | F40: 62387963 | G40: =B40/$B$43*100 -> 6.0670244 | H40: =C40/$C$43*100 -> 7.4098381 | I40: =D40/$D$43*100 -> 7.9194316 | J40: =E40/$E$43*100 -> 8.70984 | K40: =F40/$F$43*100 -> 7.3142544 | L40: =(C40-B40)/B40*100 -> 38.470192 | M40: =(D40-C40)/C40*100 -> 9.8332264 | N40: =(E40-D40)/D40*100 -> 56.843382 | O40: =(F40-E40)/E40*100 -> -3.8393875
...

Sheet ОПиУ
A1: тыс.тенге | B1: 2021 | C1: 2022 | D1: 2023 | E1: 2024 | F1: 2025 | G1: Удельный вес 2021,% | H1: Удельный вес 2022,% | I1: Удельный вес 2023,% | J1: Удельный вес 2024,% | K1: Удельный вес 2025,% | L1: Темп прироста 2021-2022,% | M1: Темп прироста 2022-2023,% | N1: Темп прироста 2023-2024,% | O1: Темп прироста 2024-2025,%
A2: Выручка и прочие доходы
A3: Пассажирские перевозки | B3: 305252639 | C3: 462171919 | D3: 521074736 | E3: 585810042 | F3: 721046502 | G3: =B3/$B$7*100 -> 93.950853 | H3: =C3/$C$7*100 -> 96.692364 | I3: =D3/$D$7*100 -> 97.366299 | J3: =E3/$E$7*100 -> 95.075567 | K3: =F3/$F$7*100 -> 95.003703 | L3: =(C3-B3)/B3*100 -> 51.406363 | M3: =(D3-C3)/C3*100 -> 12.744785 | N3: =(E3-D3)/D3*100 -> 12.423421 | O3: =(F3-E3)/E3*100 -> 23.085378
A4: Груз и почта | B4: 14304293 | C4: 10209425 | D4: 10284481 | E4: 12413214 | F4: 14272406 | G4: =B4/$B$7*100 -> 4.4025845 | H4: =C4/$C$7*100 -> 2.1359442 | I4: =D4/$D$7*100 -> 1.921724 | J4: =E4/$E$7*100 -> 2.0146349 | K4: =F4/$F$7*100 -> 1.8805048 | L4: =(C4-B4)/B4*100 -> -28.626846 | M4: =(D4-C4)/C4*100 -> 0.73516383 | N4: =(E4-D4)/D4*100 -> 20.698497 | O4: =(F4-E4)/E4*100 -> 14.977523
A5: Прочие доходы | B5: 3360585 | C5: 5600474 | D5: 3810285 | E5: 5427382 | F5: 4391707 | G5: =B5/$B$7*100 -> 1.034323 | H5: =C5/$C$7*100 -> 1.1716918 | I5: =D5/$D$7*100 -> 0.71197723 | J5: =E5/$E$7*100 -> 0.88085111 | K5: =F5/$F$7*100 -> 0.57864288 | L5: =(C5-B5)/B5*100 -> 66.651759 | M5: =(D5-C5)/C5*100 -> -31.964955 | N5: =(E5-D5)/D5*100 -> 42.440316 | O5: =(F5-E5)/E5*100 -> -19.082405
A6: Прибыль от продажи с обратной арендой | B6: 1989207 | C6: 0 | D6: 0 | E6: 12501395 | F6: 19256118 | G6: =B6/$B$7*100 -> 0.61223941 | H6: =C6/$C$7*100 -> 0 | I6: =D6/$D$7*100 -> 0 | J6: =E6/$E$7*100 -> 2.0289465 | K6: =F6/$F$7*100 -> 2.5371491 | L6: =(C6-B6)/B6*100 -> -100 | M6: 0 | N6: 0 | O6: =(F6-E6)/E6*100 -> 54.031754
A7: Всего выручки и прочих доходов | B7: 324906724 | C7: 477981818 | D7: 535169502 | E7: 616152033 | F7: 758966733 | G7: =B7/$B$7*100 -> 100 | H7: =C7/$C$7*100 -> 100 | I7: =D7/$D$7*100 -> 100 | J7: =E7/$E$7*100 -> 100 | K7: =F7/$F$7*100 -> 100 | L7: =(C7-B7)/B7*100 -> 47.113551 | M7: =(D7-C7)/C7*100 -> 11.964406 | N7: =(E7-D7)/D7*100 -> 15.132127 | O7: =(F7-E7)/E7*100 -> 23.178484
A8: Операционные расходы
A9: Топливо | B9: -58279112 | C9: -106940565 | D9: -127357770 | E9: -143373122 | F9: -173137790 | G9: =B9/$B$7*100 -> -17.937182 | H9: =C9/$C$7*100 -> -22.373354 | I9: =D9/$D$7*100 -> -23.797651 | J9: =E9/$E$7*100 -> -23.269114 | K9: =F9/$F$7*100 -> -22.812303 | L9: =(C9-B9)/B9*100 -> 83.497245 | M9: =(D9-C9)/C9*100 -> 19.092105 | N9: =(E9-D9)/D9*100 -> 12.575088 | O9: =(F9-E9)/E9*100 -> 20.760284
A10: Расходы по персоналу и экипажу | B10: -49590527 | C10: -68827926 | D10: -88102136 | E10: -106675293 | F10: -136144112 | G10: =B10/$B$7*100 -> -15.263004 | H10: =C10/$C$7*100 -> -14.399695 | I10: =D10/$D$7*100 -> -16.462473 | J10: =E10/$E$7*100 -> -17.313145 | K10: =F10/$F$7*100 -> -17.938087 | L10: =(C10-B10)/B10*100 -> 38.792488 | M10: =(D10-C10)/C10*100 -> 28.003473 | N10: =(E10-D10)/D10*100 -> 21.081392 | O10: =(F10-E10)/E10*100 -> 27.624784
A11: Износ и амортизация | B11: -51484170 | C11: -62243853 | D11: -73944311 | E11: -88717693 | F11: -119792081 | G11: =B11/$B$7*100 -> -15.845831 | H11: =C11/$C$7*100 -> -13.022222 | I11: =D11/$D$7*100 -> -13.816989 | J11: =E11/$E$7*100 -> -14.398669 | K11: =F11/$F$7*100 -> -15.783575 | L11: =(C11-B11)/B11*100 -> 20.899012 | M11: =(D11-C11)/C11*100 -> 18.797773 | N11: =(E11-D11)/D11*100 -> 19.979065 | O11: =(F11-E11)/E11*100 -> 35.026145
A12: Инженерно-техническое обслуживание | B12: -40324060 | C12: -58228907 | D12: -49388554 | E12: -55443453 | F12: -76101528 | G12: =B12/$B$7*100 -> -12.410965 | H12: =C12/$C$7*100 -> -12.182243 | I12: =D12/$D$7*100 -> -9.2285816 | J12: =E12/$E$7*100 -> -8.9983397 | K12: =F12/$F$7*100 -> -10.026991 | L12: =(C12-B12)/B12*100 -> 44.402392 | M12: =(D12-C12)/C12*100 -> -15.182069 | N12: =(E12-D12)/D12*100 -> 12.259721 | O12: =(F12-E12)/E12*100 -> 37.259719
A13: Аэропортовое обслуживание и навигация | B13: -29879880 | C13: -39205987 | D13: -48241120 | E13: -56732135 | F13: -73605152 | G13: =B13/$B$7*100 -> -9.1964486 | H13: =C13/$C$7*100 -> -8.2024013 | I13: =D13/$D$7*100 -> -9.0141758 | J13: =E13/$E$7*100 -> -9.2074897 | K13: =F13/$F$7*100 -> -9.6980736 | L13: =(C13-B13)/B13*100 -> 31.211996 | M13: =(D13-C13)/C13*100 -> 23.045289 | N13: =(E13-D13)/D13*100 -> 17.601198 | O13: =(F13-E13)/E13*100 -> 29.741551
A14: Обслуживание пассажиров | B14: -25961531 | C14: -37131951 | D14: -46124472 | E14: -55787727 | F14: -73426414 | G14: =B14/$B$7*100 -> -7.9904567 | H14: =C14/$C$7*100 -> -7.7684861 | I14: =D14/$D$7*100 -> -8.618666 | J14: =E14/$E$7*100 -> -9.0542145 | K14: =F14/$F$7*100 -> -9.6745234 | L14: =(C14-B14)/B14*100 -> 43.026815 | M14: =(D14-C14)/C14*100 -> 24.217744 | N14: =(E14-D14)/D14*100 -> 20.950386 | O14: =(F14-E14)/E14*100 -> 31.617504
A15: Расходы по реализации | B15: -10686310 | C15: -15334093 | D15: -18444763 | E15: -20777116 | F15: -26630517 | G15: =B15/$B$7*100 -> -3.2890393 | H15: =C15/$C$7*100 -> -3.2080913 | I15: =D15/$D$7*100 -> -3.4465273 | J15: =E15/$E$7*100 -> -3.3720762 | K15: =F15/$F$7*100 -> -3.5087858 | L15: =(C15-B15)/B15*100 -> 43.492871 | M15: =(D15-C15)/C15*100 -> 20.285973 | N15: =(E15-D15)/D15*100 -> 12.645069 | O15: =(F15-E15)/E15*100 -> 28.172346
A16: Страхование | B16: -3428108 | C16: -3880892 | D16: -5011359 | E16: -6013245 | F16: -7057271 | G16: =B16/$B$7*100 -> -1.0551053 | H16: =C16/$C$7*100 -> -0.81193298 | I16: =D16/$D$7*100 -> -0.93640594 | J16: =E16/$E$7*100 -> -0.97593527 | K16: =F16/$F$7*100 -> -0.92985248 | L16: =(C16-B16)/B16*100 -> 13.207985 | M16: =(D16-C16)/C16*100 -> 29.129051 | N16: =(E16-D16)/D16*100 -> 19.992301 | O16: =(F16-E16)/E16*100 -> 17.362106
A17: Информационные технологии | B17: -1951534 | C17: -2646693 | D17: -2980328 | E17: -3224735 | F17: -4203971 | G17: =B17/$B$7*100 -> -0.60064439 | H17: =C17/$C$7*100 -> -0.55372253 | I17: =D17/$D$7*100 -> -0.55689422 | J17: =E17/$E$7*100 -> -0.52336677 | K17: =F17/$F$7*100 -> -0.55390715 | L17: =(C17-B17)/B17*100 -> 35.621158 | M17: =(D17-C17)/C17*100 -> 12.605731 | N17: =(E17-D17)/D17*100 -> 8.2006746 | O17: =(F17-E17)/E17*100 -> 30.366402
A18: Консультационные и профессиональные услуги | B18: -1448480 | C18: -1976378 | D18: -2631258 | E18: -3874604 | F18: -3088882 | G18: =B18/$B$7*100 -> -0.4458141 | H18: =C18/$C$7*100 -> -0.41348393 | I18: =D18/$D$7*100 -> -0.49166815 | J18: =E18/$E$7*100 -> -0.62883895 | K18: =F18/$F$7*100 -> -0.40698516 | L18: =(C18-B18)/B18*100 -> 36.444963 | M18: =(D18-C18)/C18*100 -> 33.135362 | N18: =(E18-D18)/D18*100 -> 47.252911 | O18: =(F18-E18)/E18*100 -> -20.278769
A19: Налоги | B19: -1066338 | C19: -677929 | D19: -1787829 | E19: -2043010 | F19: -2931190 | G19: =B19/$B$7*100 -> -0.32819819 | H19: =C19/$C$7*100 -> -0.14183155 | I19: =D19/$D$7*100 -> -0.3340678 | J19: =E19/$E$7*100 -> -0.33157563 | K19: =F19/$F$7*100 -> -0.38620797 | L19: =(C19-B19)/B19*100 -> -36.424567 | M19: =(D19-C19)/C19*100 -> 163.71921 | N19: =(E19-D19)/D19*100 -> 14.273233 | O19: =(F19-E19)/E19*100 -> 43.47409
A20: Расходы по имуществу и офису | B20: -1124388 | C20: -1144309 | D20: -1766071 | E20: -2200684 | F20: -2525083 | G20: =B20/$B$7*100 -> -0.34606486 | H20: =C20/$C$7*100 -> -0.23940429 | I20: =D20/$D$7*100 -> -0.33000218 | J20: =E20/$E$7*100 -> -0.35716575 | K20: =F20/$F$7*100 -> -0.33270009 | L20: =(C20-B20)/B20*100 -> 1.7717194 | M20: =(D20-C20)/C20*100 -> 54.335149 | N20: =(E20-D20)/D20*100 -> 24.609033 | O20: =(F20-E20)/E20*100 -> 14.740826
A21: Переменные расходы по аренде воздушных судов | B21: -1561520 | C21: -1780324 | D21: -1000743 | E21: -2384213 | F21: -1162524 | G21: =B21/$B$7*100 -> -0.48060563 | H21: =C21/$C$7*100 -> -0.37246689 | I21: =D21/$D$7*100 -> -0.18699552 | J21: =E21/$E$7*100 -> -0.38695206 | K21: =F21/$F$7*100 -> -0.15317193 | L21: =(C21-B21)/B21*100 -> 14.012244 | M21: =(D21-C21)/C21*100 -> -43.788715 | N21: =(E21-D21)/D21*100 -> 138.24428 | O21: =(F21-E21)/E21*100 -> -51.240766
A22: Убытки от обесценения дебиторской задолженности | B22: -49254 | C22: -185249 | D22: -57402 | E22: 0 | F22: 0 | G22: =B22/$B$7*100 -> -0.015159428 | H22: =C22/$C$7*100 -> -0.038756495 | I22: =D22/$D$7*100 -> -0.010725948 | J22: =E22/$E$7*100 -> 0 | K22: =F22/$F$7*100 -> 0 | L22: =(C22-B22)/B22*100 -> 276.10955 | M22: =(D22-C22)/C22*100 -> -69.013598 | N22: =(E22-D22)/D22*100 -> -100 | O22: 0
A23: Прочие операционные расходы | B23: -4456439 | C23: -7666288 | D23: -7045247 | E23: -6582456 | F23: -13311137 | G23: =B23/$B$7*100 -> -1.3716057 | H23: =C23/$C$7*100 -> -1.6038869 | I23: =D23/$D$7*100 -> -1.3164515 | J23: =E23/$E$7*100 -> -1.0683169 | K23: =F23/$F$7*100 -> -1.7538499 | L23: =(C23-B23)/B23*100 -> 72.027217 | M23: =(D23-C23)/C23*100 -> -8.1009349 | N23: =(E23-D23)/D23*100 -> -6.56884 | O23: =(F23-E23)/E23*100 -> 102.22144
A24: Всего операционные расходы | B24: -281291651 | C24: -407871344 | D24: -473883363 | E24: -553829486 | F24: -713117652 | G24: =B24/$B$7*100 -> -86.576125 | H24: =C24/$C$7*100 -> -85.331979 | I24: =D24/$D$7*100 -> -88.548275 | J24: =E24/$E$7*100 -> -89.8852 | K24: =F24/$F$7*100 -> -93.959013 | L24: =(C24-B24)/B24*100 -> 44.999449 | M24: =(D24-C24)/C24*100 -> 16.18452 | N24: =(E24-D24)/D24*100 -> 16.870422 | O24: =(F24-E24)/E24*100 -> 28.761229
A25: Операционная прибыль | B25: 43615073 | C25: 70110474 | D25: 61286139 | E25: 62322547 | F25: 45849081 | G25: =B25/$B$7*100 -> 13.423875 | H25: =C25/$C$7*100 -> 14.668021 | I25: =D25/$D$7*100 -> 11.451725 | J25: =E25/$E$7*100 -> 10.1148 | K25: =F25/$F$7*100 -> 6.0409869 | L25: =(C25-B25)/B25*100 -> 60.748267 | M25: =(D25-C25)/C25*100 -> -12.586329 | N25: =(E25-D25)/D25*100 -> 1.6910969 | O25: =(F25-E25)/E25*100 -> -26.432594
A26: Финансовые доходы | B26: 1026620 | C26: 3261294 | D26: 6757281 | E26: 10376957 | F26: 11633517 | G26: =B26/$B$7*100 -> 0.31597376 | H26: =C26/$C$7*100 -> 0.68230503 | I26: =D26/$D$7*100 -> 1.2626431 | J26: =E26/$E$7*100 -> 1.6841553 | K26: =F26/$F$7*100 -> 1.5328099 | L26: =(C26-B26)/B26*100 -> 217.67295 | M26: =(D26-C26)/C26*100 -> 107.19632 | N26: =(E26-D26)/D26*100 -> 53.567049 | O26: =(F26-E26)/E26*100 -> 12.109138
A27: Финансовые расходы | B27: -20040053 | C27: -18073217 | D27: -22765053 | E27: -30618503 | F27: -42893475 | G27: =B27/$B$7*100 -> -6.1679404 | H27: =C27/$C$7*100 -> -3.7811516 | I27: =D27/$D$7*100 -> -4.2538024 | J27: =E27/$E$7*100 -> -4.9693097 | K27: =F27/$F$7*100 -> -5.6515619 | L27: =(C27-B27)/B27*100 -> -9.8145249 | M27: =(D27-C27)/C27*100 -> 25.96016 | N27: =(E27-D27)/D27*100 -> 34.497833 | O27: =(F27-E27)/E27*100 -> 40.090046
A28: Убыток от курсовой разницы, нетто | B28: -5330611 | C28: -6923638 | D28: -6280403 | E28: -9939963 | F28: -4142993 | G28: =B28/$B$7*100 -> -1.6406589 | H28: =C28/$C$7*100 -> -1.4485149 | I28: =D28/$D$7*100 -> -1.1735353 | J28: =E28/$E$7*100 -> -1.6132322 | K28: =F28/$F$7*100 -> -0.54587281 | L28: =(C28-B28)/B28*100 -> 29.88451 | M28: =(D28-C28)/C28*100 -> -9.2904193 | N28: =(E28-D28)/D28*100 -> 58.269509 | O28: =(F28-E28)/E28*100 -> -58.319835
A29: Прибыль до налогообложения | B29: 19271029 | C29: 48374913 | D29: 38997964 | E29: 32141038 | F29: 10446130 | G29: =B29/$B$7*100 -> 5.9312497 | H29: =C29/$C$7*100 -> 10.12066 | I29: =D29/$D$7*100 -> 7.2870303 | J29: =E29/$E$7*100 -> 5.2164135 | K29: =F29/$F$7*100 -> 1.376362 | L29: =(C29-B29)/B29*100 -> 151.02403 | M29: =(D29-C29)/C29*100 -> -19.383909 | N29: =(E29-D29)/D29*100 -> -17.582779 | O29: =(F29-E29)/E29*100 -> -67.499089
A30: Расход по подоходному налогу | B30: -3785461 | C30: -10792015 | D30: -8258890 | E30: -6618444 | F30: -3423268 | G30: =B30/$B$7*100 -> -1.1650916 | H30: =C30/$C$7*100 -> -2.2578296 | I30: =D30/$D$7*100 -> -1.5432288 | J30: =E30/$E$7*100 -> -1.0741576 | K30: =F30/$F$7*100 -> -0.45104322 | L30: =(C30-B30)/B30*100 -> 185.09117 | M30: =(D30-C30)/C30*100 -> -23.472215 | N30: =(E30-D30)/D30*100 -> -19.86279 | O30: =(F30-E30)/E30*100 -> -48.276846
A31: Прибыль за год | B31: 15485568 | C31: 37582898 | D31: 30739074 | E31: 25522594 | F31: 7022862 | G31: =B31/$B$7*100 -> 4.7661581 | H31: =C31/$C$7*100 -> 7.86283 | I31: =D31/$D$7*100 -> 5.7438015 | J31: =E31/$E$7*100 -> 4.1422559 | K31: =F31/$F$7*100 -> 0.92531882 | L31: =(C31-B31)/B31*100 -> 142.69628 | M31: =(D31-C31)/C31*100 -> -18.209942 | N31: =(E31-D31)/D31*100 -> -16.970192 | O31: =(F31-E31)/E31*100 -> -72.483745
A32: Базовая и разводненная прибыль на акцию - базовая и разводненная, тенге | B32: 910.916 | C32: 2210.759 | D32: 100.454 | E32: 73.156 | F32: 19.823 | G32: =B32/$B$7*100 -> 0.00028036231 | H32: =C32/$C$7*100 -> 0.00046251948 | I32: =D32/$D$7*100 -> 1.8770502e-05 | J32: =E32/$E$7*100 -> 1.1873044e-05 | K32: =F32/$F$7*100 -> 2.6118404e-06 | L32: =(C32-B32)/B32*100 -> 142.69625 | M32: =(D32-C32)/C32*100 -> -95.456131 | N32: =(E32-D32)/D32*100 -> -27.174627 | O32: =(F32-E32)/E32*100 -> -72.903111

Sheet ОДДС
A1: Отчет о движении денежных средств
A2: тыс. тенге
A3: Показатель | B3: 2021 | C3: 2022 | D3: 2023 | E3: 2024 | F3: 2025
A4: ОПЕРАЦИОННАЯ ДЕЯТЕЛЬНОСТЬ
A5: Прибыль до налогообложения | B5: 19271029 | C5: 48374913 | D5: 39683633 | E5: 31385844 | F5: 10503068
A6: Корректировки:
A7: Износ и амортизация основных средств и нематериальных активов | B7: 51484170 | C7: 62243853 | D7: 73820615 | E7: 89033552 | F7: 119929168
A8: Доход от выбытия основных средств | B8: -3054489 | C8: -1026474 | D8: -1594326 | E8: -12111266 | F8: -20227280
A9: Изменение резерва под обесценение дебиторской задолженности, авансов, гарантийных депозитов, денежных средств и их эквивалентов | B9: -154649 | C9: -1118045 | D9: -34630 | E9: -541249 | F9: 99706
A10: Изменение резерва на неликвидные товарно-материальные запасы | B10: -59218 | C10: 1975459 | D10: -282960 | E10: 166140 | F10: 976702
A11: Изменение в резерве отпусков | B11: 135478 | C11: -34996 | D11: -143986 | E11: 553486 | F11: 739182
A12: Изменение в резерве по техническому обслуживанию воздушных судов | B12: 25899549 | C12: 37199540 | D12: 39108600 | E12: 44852585 | F12: 56069783
A13: Изменение в резерве по программе лояльности клиентов | B13: -602832 | C13: 442982 | D13: 1263978 | E13: 1914609 | F13: -400390
A14: Убыток от курсовой разницы, нетто | B14: 5330611 | C14: 6923638 | D14: 6289363 | E14: 9762717 | F14: 4127100
A15: Финансовые доходы | B15: -763039 | C15: -2929191 | D15: -6525390 | E15: -10251724 | F15: -11631156
A16: Финансовые расходы | B16: 19931534 | C16: 18019259 | D16: 22537453 | E16: 30400300 | F16: 42929986
A17: Эффект отсрочки платежей по аренде, связанной с COVID-19 | B17: 377748 | C17: 0 | D17: 0 | E17: 0 | F17: 0
A18: Доход от досрочного возврата двигателя/воздушных судов | B18: -209440 | C18: 0 | D18: 0 | E18: -1353122 | F18: 0
... A21: Выплаты, основанные на акциях | B21: 0 | C21: 0 | D21: 0 | E21: 2875208 | F21: 487046
A22: Денежные средства, полученные от операционной деятельности до изменений в оборотном капитале | B22: =B5+B7+B8+B9+B10+B11+B12+B13+B14+B15+B16+B17+B18+B19+B20+B21 -> 117586452 | C22: =C5+C7+C8+C9+C10+C11+C12+C13+C14+C15+C16+C17+C18+C19+C20+C21 -> 170070938 | D22: =D5+D7+D8+D9+D10+D11+D12+D13+D14+D15+D16+D17+D18+D19+D20+D21 -> 174122350 | E22: =E5+E7+E8+E9+E10+E11+E12+E13+E14+E15+E16+E17+E18+E19+E20+E21 -> 186687080 | F22: =F5+F7+F8+F9+F10+F11+F12+F13+F14+F15+F16+F17+F18+F19+F20+F21 -> 200595550
A23: Изменение торговой и прочей дебиторской задолженности | B23: -1631695 | C23: -1753047 | D23: -378647 | E23: -844348 | F23: -15610002
A24: Изменение в предоплатах и авансах выданных | B24: -2727444 | C24: 1506230 | D24: -2563042 | E24: -4801113 | F24: -10538566
A25: Изменение товарно-материальных запасов | B25: -1497495 | C25: -221491 | D25: -7649028 | E25: 770927 | F25: -11567469
A26: Изменение торговой и прочей кредиторской задолженности и резерве по техническому обслуживанию воздушных судов | B26: 1738628 | C26: -337071 | D26: -8198544 | E26: -8395476 | F26: -35710953
A27: Изменение доходов будущих периодов | B27: 8760455 | C27: 10098326 | D27: 657050 | E27: 1607274 | F27: 5243704
A28: Изменение по прочим финансовым инструментам | B28: -3147644 | C28: 2760578 | D28: -58779 | E28: 420291 | F28: 117455
A29: Денежные средства, полученные от операционной деятельности | B29: =B22+B23+B24+B25+B26+B27+B28 -> 119081257 | C29: =C22+C23+C24+C25+C26+C27+C28 -> 182124463 | D29: =D22+D23+D24+D25+D26+D27+D28 -> 155931360 | E29: =E22+E23+E24+E25+E26+E27+E28 -> 175444635 | F29: =F22+F23+F24+F25+F26+F27+F28 -> 132529719
A30: Уплаченный подоходный налог | B30: -1707547 | C30: -21822810 | D30: -19519671 | E30: -12550855 | F30: -16566867
A31: Полученное вознаграждение | B31: 693694 | C31: 2929191 | D31: 6416034 | E31: 10233368 | F31: 11628024
A32: Чистые денежные средства, полученные от операционной деятельности | B32: =B29+B30+B31 -> 118067404 | C32: =C29+C30+C31 -> 163230844 | D32: =D29+D30+D31 -> 142827723 | E32: =E29+E30+E31 -> 173127148 | F32: =F29+F30+F31 -> 127590876
A33: ИНВЕСТИЦИОННАЯ ДЕЯТЕЛЬНОСТЬ
A34: Приобретение основных средств | B34: -13497482 | C34: -22227370 | D34: -19035768 | E34: -46099340 | F34: -28152607
A35: Поступления от продажи с обратной арендой | B35: 3714556 | C35: 0 | D35: 0 | E35: 42593931 | F35: 72947775
A36: Поступления от продажи основных средств | B36: 1696451 | C36: 908988 | D36: 2269146 | E36: 1286760 | F36: 1868836
A37: Приобретение нематериальных активов | B37: -231449 | C37: -306179 | D37: -964159 | E37: -1735291 | F37: -749623
A38: Размещение банковских и гарантийных депозитов | B38: -1753113 | C38: -11643697 | D38: -4546950 | E38: -5988095 | F38: -29779226
A39: Погашение банковских и гарантийных депозитов | B39: 4508675 | C39: 5471423 | D39: 1310455 | E39: 1432662 | F39: 1463748
A40: Чистые денежные средства, использованные в/полученные от инвестиционной деятельности | B40: =B34+B35+B36+B37+B38+B39 -> -5562362 | C40: =C34+C35+C36+C37+C38+C39 -> -27796835 | D40: =D34+D35+D36+D37+D38+D39 -> -20967276 | E40: =E34+E35+E36+E37+E38+E39 -> -8509373 | F40: =F34+F35+F36+F37+F38+F39 -> 17598903
A41: ФИНАНСОВАЯ ДЕЯТЕЛЬНОСТЬ
A42: Выплаты по аренде | B42: -39916368 | C42: -80533966 | D42: -78965381 | E42: -89579507 | F42: -99581823
...

Sheet Коэффициенты
A1: Коэффициент | B1: 2021 | C1: 2022 | D1: 2023 | E1: 2024 | F1: 2025
A2: Расчетная валовая маржа | B2: =(ОПиУ!B7+ОПиУ!B9+ОПиУ!B10+ОПиУ!B12+ОПиУ!B13+ОПиУ!B14)/ОПиУ!B7 -> 0.37201943 | C2: =(ОПиУ!C7+ОПиУ!C9+ОПиУ!C10+ОПиУ!C12+ОПиУ!C13+ОПиУ!C14)/ОПиУ!C7 -> 0.3507382 | D2: =(ОПиУ!D7+ОПиУ!D9+ОПиУ!D10+ОПиУ!D12+ОПиУ!D13+ОПиУ!D14)/ОПиУ!D7 -> 0.32878452 | E2: =(ОПиУ!E7+ОПиУ!E9+ОПиУ!E10+ОПиУ!E12+ОПиУ!E13+ОПиУ!E14)/ОПиУ!E7 -> 0.32157697 | F2: =(ОПиУ!F7+ОПиУ!F9+ОПиУ!F10+ОПиУ!F12+ОПиУ!F13+ОПиУ!F14)/ОПиУ!F7 -> 0.29850022
A3: Операционная маржа | B3: =ОПиУ!B25/ОПиУ!B7 -> 0.13423875 | C3: =ОПиУ!C25/ОПиУ!C7 -> 0.14668021 | D3: =ОПиУ!D25/ОПиУ!D7 -> 0.11451725 | E3: =ОПиУ!E25/ОПиУ!E7 -> 0.101148 | F3: =ОПиУ!F25/ОПиУ!F7 -> 0.060409869
A4: Чистая маржа | B4: =ОПиУ!B31/ОПиУ!B7 -> 0.047661581 | C4: =ОПиУ!C31/ОПиУ!C7 -> 0.0786283 | D4: =ОПиУ!D31/ОПиУ!D7 -> 0.057438015 | E4: =ОПиУ!E31/ОПиУ!E7 -> 0.041422559 | F4: =ОПиУ!F31/ОПиУ!F7 -> 0.0092531882
A5: Коэффициент текущей ликвидности | B5: =(Баланс!B11+Баланс!B12+Баланс!B13+Баланс!B14+Баланс!B15+Баланс!B16+Баланс!B17+Баланс!B18)/(Баланс!B36+Баланс!B37+Баланс!B38+Баланс!B39+Баланс!B40+Баланс!B41+Баланс!B42) -> 0.92607718 | C5: =(Баланс!C11+Баланс!C12+Баланс!C13+Баланс!C14+Баланс!C15+Баланс!C16+Баланс!C17+Баланс!C18)/(Баланс!C36+Баланс!C37+Баланс!C38+Баланс!C39+Баланс!C40+Баланс!C41+Баланс!C42) -> 0.91726416 | D5: =(Баланс!D11+Баланс!D12+Баланс!D13+Баланс!D14+Баланс!D15+Баланс!D16+Баланс!D17+Баланс!D18)/(Баланс!D36+Баланс!D37+Баланс!D38+Баланс!D39+Баланс!D40+Баланс!D41+Баланс!D42) -> 0.91271811 | E5: =(Баланс!E11+Баланс!E12+Баланс!E13+Баланс!E14+Баланс!E15+Баланс!E16+Баланс!E17+Баланс!E18)/(Баланс!E36+Баланс!E37+Баланс!E38+Баланс!E39+Баланс!E40+Баланс!E41+Баланс!E42) -> 1.5497035 | F5: =(Баланс!F11+Баланс!F12+Баланс!F13+Баланс!F14+Баланс!F15+Баланс!F16+Баланс!F17+Баланс!F18)/(Баланс!F36+Баланс!F37+Баланс!F38+Баланс!F39+Баланс!F40+Баланс!F41+Баланс!F42) -> 1.2382705
A6: Коэффициент быстрой ликвидности | B6: =(Баланс!B14+Баланс!B16+Баланс!B17+Баланс!B18)/(Баланс!B36+Баланс!B37+Баланс!B38+Баланс!B39+Баланс!B40+Баланс!B41+Баланс!B42) -> 0.68370244 | C6: =(Баланс!C14+Баланс!C16+Баланс!C17+Баланс!C18)/(Баланс!C36+Баланс!C37+Баланс!C38+Баланс!C39+Баланс!C40+Баланс!C41+Баланс!C42) -> 0.69841354 | D6: =(Баланс!D14+Баланс!D16+Баланс!D17+Баланс!D18)/(Баланс!D36+Баланс!D37+Баланс!D38+Баланс!D39+Баланс!D40+Баланс!D41+Баланс!D42) -> 0.65856852 | E6: =(Баланс!E14+Баланс!E16+Баланс!E17+Баланс!E18)/(Баланс!E36+Баланс!E37+Баланс!E38+Баланс!E39+Баланс!E40+Баланс!E41+Баланс!E42) -> 1.2496048 | F6: =(Баланс!F14+Баланс!F16+Баланс!F17+Баланс!F18)/(Баланс!F36+Баланс!F37+Баланс!F38+Баланс!F39+Баланс!F40+Баланс!F41+Баланс!F42) -> 0.96336416
A7: Коэффициент абсолютной ликвидности | B7: =(Баланс!B17+Баланс!B18)/(Баланс!B36+Баланс!B37+Баланс!B38+Баланс!B39+Баланс!B40+Баланс!B41+Баланс!B42) -> 0.6406644 | C7: =(Баланс!C17+Баланс!C18)/(Баланс!C36+Баланс!C37+Баланс!C38+Баланс!C39+Баланс!C40+Баланс!C41+Баланс!C42) -> 0.63635728 | D7: =(Баланс!D17+Баланс!D18)/(Баланс!D36+Баланс!D37+Баланс!D38+Баланс!D39+Баланс!D40+Баланс!D41+Баланс!D42) -> 0.60263231 | E7: =(Баланс!E17+Баланс!E18)/(Баланс!E36+Баланс!E37+Баланс!E38+Баланс!E39+Баланс!E40+Баланс!E41+Баланс!E42) -> 1.1910514 | F7: =(Баланс!F17+Баланс!F18)/(Баланс!F36+Баланс!F37+Баланс!F38+Баланс!F39+Баланс!F40+Баланс!F41+Баланс!F42) -> 0.8292957
A8: Коэффициент автономии | B8: =Баланс!B29/Баланс!B19 -> 0.058042464 | C8: =Баланс!C29/Баланс!C19 -> 0.12172919 | D8: =Баланс!D29/Баланс!D19 -> 0.1566002 | E8: =Баланс!E29/Баланс!E19 -> 0.21760269 | F8: =Баланс!F29/Баланс!F19 -> 0.17957669
A9: Коэффициент финансового левериджа | B9: =Баланс!B43/Баланс!B29 -> 16.228766 | C9: =Баланс!C43/Баланс!C29 -> 7.2149563 | D9: =Баланс!D43/Баланс!D29 -> 5.3856881 | E9: =Баланс!E43/Баланс!E29 -> 3.5955314 | F9: =Баланс!F43/Баланс!F29 -> 4.5686516
A10: Покрытие финансовых расходов | B10: =ОПиУ!B25/(-ОПиУ!B27) -> 2.1763951 | C10: =ОПиУ!C25/(-ОПиУ!C27) -> 3.8792471 | D10: =ОПиУ!D25/(-ОПиУ!D27) -> 2.6921149 | E10: =ОПиУ!E25/(-ОПиУ!E27) -> 2.0354538 | F10: =ОПиУ!F25/(-ОПиУ!F27) -> 1.0689057
A11: Чистый оборотный капитал, тыс. тг | B11: =(Баланс!B11+Баланс!B12+Баланс!B13+Баланс!B14+Баланс!B15+Баланс!B16+Баланс!B17+Баланс!B18)-(Баланс!B36+Баланс!B37+Баланс!B38+Баланс!B39+Баланс!B40+Баланс!B41+Баланс!B42) -> -11645647 | C11: =(Баланс!C11+Баланс!C12+Баланс!C13+Баланс!C14+Баланс!C15+Баланс!C16+Баланс!C17+Баланс!C18)-(Баланс!C36+Баланс!C37+Баланс!C38+Баланс!C39+Баланс!C40+Баланс!C41+Баланс!C42) -> -15311400 | D11: =(Баланс!D11+Баланс!D12+Баланс!D13+Баланс!D14+Баланс!D15+Баланс!D16+Баланс!D17+Баланс!D18)-(Баланс!D36+Баланс!D37+Баланс!D38+Баланс!D39+Баланс!D40+Баланс!D41+Баланс!D42) -> -18089671 | E11: =(Баланс!E11+Баланс!E12+Баланс!E13+Баланс!E14+Баланс!E15+Баланс!E16+Баланс!E17+Баланс!E18)-(Баланс!E36+Баланс!E37+Баланс!E38+Баланс!E39+Баланс!E40+Баланс!E41+Баланс!E42) -> 118511550 | F11: =(Баланс!F11+Баланс!F12+Баланс!F13+Баланс!F14+Баланс!F15+Баланс!F16+Баланс!F17+Баланс!F18)-(Баланс!F36+Баланс!F37+Баланс!F38+Баланс!F39+Баланс!F40+Баланс!F41+Баланс!F42) -> 68719220

Sheet Инпут
A1: Год | B1: Компания | C1: Валюта | D1: Масштаб | E1: Источник | F1: Выручка всего | G1: Операционная прибыль | H1: Чистая прибыль | I1: Активы всего | J1: Обязательства всего | K1: Капитал | L1: Денежные средства | M1: Дебиторская задолженность | N1: Запасы | O1: Основные средства | P1: Нематериальные активы | Q1: Займы всего | R1: Обязательства по аренде всего | S1: Итого долг | T1: CFO | U1: CFI | V1: CFF | W1: Capex | X1: Операционная маржа | Y1: Чистая маржа | Z1: ROA | AA1: ROE | AB1: Долг / Активы | AC1: Долг / Капитал | AD1: CFO / чистая прибыль | AE1: FCF
A2: 2021 | B2: Air Astana | C2: KZT | D2: тыс. тенге | E2: Финансовая отчетность Air Astana; листы Баланс и ОДДС,ОПиУ | F2: =ОПиУ!B7 -> 324906724 | G2: =ОПиУ!B25 -> 43615073 | H2: =ОПиУ!B31 -> 15485568 | I2: =Баланс!B19 -> 475926936 | J2: =Баланс!B43 -> 448302964 | K2: =Баланс!B29 -> 27623972 | L2: =Баланс!B17 -> 97740953 | M2: =Баланс!B14 -> 6103061 | N2: =Баланс!B11 -> 22261449 | O2: =Баланс!B4 -> 311845960 | P2: =Баланс!B5 -> 659790 | Q2: =Баланс!B31+Баланс!B36 -> 26895095 | R2: =Баланс!B32+Баланс!B37 -> 313872397 | S2: =Q2+R2 -> 340767492 | T2: =ОДДС!B32 -> 118067404 | U2: =ОДДС!B40 -> -5562362 | V2: =ОДДС!B50 -> -101243828 | W2: =ОДДС!B58 -> 13497482 | X2: =G2/F2 -> 0.13423875 | Y2: =H2/F2 -> 0.047661581 | Z2: =H2/I2 -> 0.0325377 | AA2: =H2/K2 -> 0.56058441 | AB2: =S2/I2 -> 0.716008 | AC2: =S2/K2 -> 12.335934 | AD2: =T2/H2 -> 7.6243509 | AE2: =T2-W2 -> 104569922
A3: 2022 | B3: Air Astana | C3: KZT | D3: тыс. тенге | E3: Финансовая отчетность Air Astana; листы Баланс и ОДДС,ОПиУ | F3: =ОПиУ!C7 -> 477981818 | G3: =ОПиУ!C25 -> 70110474 | H3: =ОПиУ!C31 -> 37582898 | I3: =Баланс!C19 -> 578717319 | J3: =Баланс!C43 -> 508270527 | K3: =Баланс!C29 -> 70446792 | L3: =Баланс!C17 -> 116998633 | M3: =Баланс!C14 -> 9857684 | N3: =Баланс!C11 -> 22750814 | O3: =Баланс!C4 -> 378255700 | P3: =Баланс!C5 -> 718495 | Q3: =Баланс!C31+Баланс!C36 -> 5596214 | R3: =Баланс!C32+Баланс!C37 -> 339031770 | S3: =Q3+R3 -> 344627984 | T3: =ОДДС!C32 -> 163230844 | U3: =ОДДС!C40 -> -27796835 | V3: =ОДДС!C50 -> -119154847 | W3: =ОДДС!C58 -> 22227370 | X3: =G3/F3 -> 0.14668021 | Y3: =H3/F3 -> 0.0786283 | Z3: =H3/I3 -> 0.06494172 | AA3: =H3/K3 -> 0.53349339 | AB3: =S3/I3 -> 0.59550315 | AC3: =S3/K3 -> 4.8920323 | AD3: =T3/H3 -> 4.3432213 | AE3: =T3-W3 -> 141003474
A4: 2023 | B4: Air Astana | C4: KZT | D4: тыс. тенге | E4: Финансовая отчетность Air Astana; листы Баланс и ОДДС,ОПиУ | F4: =ОПиУ!D7 -> 535169502 | G4: =ОПиУ!D25 -> 61286139 | H4: =ОПиУ!D31 -> 30739074 | I4: =Баланс!D19 -> 619312543 | J4: =Баланс!D43 -> 522328078 | K4: =Баланс!D29 -> 96984465 | L4: =Баланс!D17 -> 124552167 | M4: =Баланс!D14 -> 10693524 | N4: =Баланс!D11 -> 30704619 | O4: =Баланс!D4 -> 387885139 | P4: =Баланс!D5 -> 1289132 | Q4: =Баланс!D31+Баланс!D36 -> 187279 | R4: =Баланс!D32+Баланс!D37 -> 326780002 | S4: =Q4+R4 -> 326967281 | T4: =ОДДС!D32 -> 142827723 | U4: =ОДДС!D40 -> -20967276 | V4: =ОДДС!D50 -> -111377266 | W4: =ОДДС!D58 -> 19035768 | X4: =G4/F4 -> 0.11451725 | Y4: =H4/F4 -> 0.057438015 | Z4: =H4/I4 -> 0.049634186 | AA4: =H4/K4 -> 0.31694843 | AB4: =S4/I4 -> 0.52795198 | AC4: =S4/K4 -> 3.3713366 | AD4: =T4/H4 -> 4.646455 | AE4: =T4-W4 -> 123791955
A5: 2024 | B5: Air Astana | C5: KZT | D5: тыс. тенге | E5: Финансовая отчетность Air Astana; листы Баланс и ОДДС,ОПиУ | F5: =ОПиУ!E7 -> 616152033 | G5: =ОПиУ!E25 -> 62322547 | H5: =ОПиУ!E31 -> 25522594 | I5: =Баланс!E19 -> 952063811 | J5: =Баланс!E43 -> 744892164 | K5: =Баланс!E29 -> 207171647 | L5: =Баланс!E17 -> 256622307 | M5: =Баланс!E14 -> 10922813 | N5: =Баланс!E11 -> 34724999 | O5: =Баланс!E4 -> 558341061 | P5: =Баланс!E5 -> 3160112 | Q5: =Баланс!E31+Баланс!E36 -> 302988 | R5: =Баланс!E32+Баланс!E37 -> 466644777 | S5: =Q5+R5 -> 466947765 | T5: =ОДДС!E32 -> 173127148 | U5: =ОДДС!E40 -> -8509373 | V5: =ОДДС!E50 -> -62191375 | W5: =ОДДС!E58 -> 46099340 | X5: =G5/F5 -> 0.101148 | Y5: =H5/F5 -> 0.041422559 | Z5: =H5/I5 -> 0.026807651 | AA5: =H5/K5 -> 0.1231954 | AB5: =S5/I5 -> 0.49045848 | AC5: =S5/K5 -> 2.2539173 | AD5: =T5/H5 -> 6.7832897 | AE5: =T5-W5 -> 127027808
A6: 2025 | B6: Air Astana | C6: KZT | D6: тыс. тенге | E6: Финансовая отчетность Air Astana; листы Баланс и ОДДС,ОПиУ | F6: =ОПиУ!F7 -> 758966733 | G6: =ОПиУ!F25 -> 45849081 | H6: =ОПиУ!F31 -> 7022862 | I6: =Баланс!F19 -> 1039663393 | J6: =Баланс!F43 -> 852964087 | K6: =Баланс!F29 -> 186699306 | L6: =Баланс!F17 -> 239053004 | M6: =Баланс!F14 -> 13142263 | N6: =Баланс!F11 -> 43686386 | O6: =Баланс!F4 -> 604500136 | P6: =Баланс!F5 -> 3286956 | Q6: =Баланс!F31+Баланс!F36 -> 2826923 | R6: =Баланс!F32+Баланс!F37 -> 527958850 | S6: =Q6+R6 -> 530785773 | T6: =ОДДС!F32 -> 127590876 | U6: =ОДДС!F40 -> 17598903 | V6: =ОДДС!F50 -> -152510081 | W6: =ОДДС!F58 -> 28152607 | X6: =G6/F6 -> 0.060409869 | Y6: =H6/F6 -> 0.0092531882 | Z6: =H6/I6 -> 0.0067549382 | AA6: =H6/K6 -> 0.037615898 | AB6: =S6/I6 -> 0.51053618 | AC6: =S6/K6 -> 2.8429981 | AD6: =T6/H6 -> 18.167932 | AE6: =T6-W6 -> 99438269

Sheet Проверки
A1: Проверка | B1: 2021 | C1: 2022 | D1: 2023 | E1: 2024 | F1: 2025
A2: Баланс сходится | B2: =Инпут!I2-Инпут!J2-Инпут!K2 -> 0 | C2: =Инпут!I3-Инпут!J3-Инпут!K3 -> 0 | D2: =Инпут!I4-Инпут!J4-Инпут!K4 -> 0 | E2: =Инпут!I5-Инпут!J5-Инпут!K5 -> 0 | F2: =Инпут!I6-Инпут!J6-Инпут!K6 -> 0
A3: Валюта | B3: =Инпут!C2 -> KZT | C3: =Инпут!C3 -> KZT | D3: =Инпут!C4 -> KZT | E3: =Инпут!C5 -> KZT | F3: =Инпут!C6 -> KZT
A4: Масштаб | B4: =Инпут!D2 -> тыс. тенге | C4: =Инпут!D3 -> тыс. тенге | D4: =Инпут!D4 -> тыс. тенге | E4: =Инпут!D5 -> тыс. тенге | F4: =Инпут!D6 -> тыс. тенге
A5: CFO | B5: =Инпут!T2 -> 118067404 | C5: =Инпут!T3 -> 163230844 | D5: =Инпут!T4 -> 142827723 | E5: =Инпут!T5 -> 173127148 | F5: =Инпут!T6 -> 127590876
A6: FCF | B6: =Инпут!T2-Инпут!W2 -> 104569922 | C6: =Инпут!T3-Инпут!W3 -> 141003474 | D6: =Инпут!T4-Инпут!W4 -> 123791955 | E6: =Инпут!T5-Инпут!W5 -> 127027808 | F6: =Инпут!T6-Инпут!W6 -> 99438269

Sheet Источники
A1: Год | B1: Документ | C1: Файл / ссылка
A2: 2021 | B2: Финансовая отчетность Air Astana за 2021 год | C2: C:/Users/malin/Downloads/финансовая_отчетность-_за_2021_год.pdf
A3: 2022 | B3: Финансовая отчетность Air Astana за 2022 год | C3: C:/Users/malin/Downloads/fs_aa_kzt_2022_signed.pdf
A4: 2023-2025 | B4: Исходный Excel с анализом | C4: C:/Users/malin/Downloads/ЭйрАстана.xlsx
A5: 2021-2022 | B5: Полный ОДДС | C5: Финансовая отчетность Air Astana за 2021-2022 годы
A6: 2023 | B6: Полный ОДДС | C6: https://ir.airastana.com/media/8dc44aa8f61bda7/aa-fs-2023-conso-usd.pdf
A7: 2024 | B7: Полный ОДДС | C7: https://ir.airastana.com/media/8dd62d1cc357574/fs-aa-usd-2024-conso-eng-final-signed.pdf
A8: 2025 | B8: Полный ОДДС | C8: https://ir.airastana.com/media/8de832fbd001d0b/fs-aa-usd-2025-eng-final-formatted-signed-final.pdf
